Workbook

Sheet 模型说明
A1: 模型说明（2023年8月）
A2: 一、模型构成
A3: （一）ICT项目效益评估模型由“综合评估表”“收入支出明细表（基础数据表）”“收入支出明细表（含税）”“收入支出明细表（不含税）”“现金流量明细表”构成。
A4: （二）“综合评估表”是ICT项目综合效益的最终评估结果展示表，包括“基础信息表”“财务价值评估”与“业务价值评估”三部分。其中，“财务价值评估”的指标值从“收入支出明细表（基础数据表）”“收入支出明细表（含税）”“收入支出明细表（不含税）”“现金流量明细表”中直接运算提取，“业务价值评估”的指标值需要手工填写。
A5: （三）“收入支出明细表（基础数据表）”：根据会计核算规范，填写预计入账的收入、支出数据，收入、付款进度即现金流入、流出情况，填写完成后，可自动生成“收入支出明细表（含税）”“收入支出明细表（不含税）”“现金流量表”三张表。
A6: （四）“收入支出明细表（基础数据表）”中含税收支与现金流入流出存在校验关系。其中含税收入合计应等于现金流入合计，含税支出合计应等于现金流出合计。
A7: 二、适用范围
A8: 本模型既适用于“售前阶段”的项目价值前评估，也可用于“售中阶段”的项目效益过程评估及“售后阶段”的项目效益后评估。
A9: 三、填表说明
A10: （一）在“收入支出明细表（基础数据表）”的黄色底纹“手工输入区”据实填写项目信息与原始测算数据，“收入支出明细表（含税）”“收入支出明细表（不含税）”“现金流量明细表”“综合评估表””将自动计算产出财务价值评价指标的结果。
A11: （二）在“综合评估表”的“业务价值评估”中填写业务价值评估指标的达成情况描述，产出完整的综合效益评估结果。
A12: （三）本模型财务指标值在某些特殊场景下可能无法计算，如有特殊情况，需结合项目实际情况进行手工调整。

Sheet 综合评估表
A1: ICT项目综合评估表
B4: 基础信息表
B5: 项目名称 | D5: 项目承建单位 | F5: 项目需求单位
B6: 项目模式（IT服务） | D6: 项目模式（IT设备）（可多选） | F6: 资产权属（可多选）
B7: 合作年限 | C7: 5 | D7: 是否涉及固定资产投资 | F7: 是否为续建项目
B10: 财务价值评估表
B11: 评价指标 | C11: 指标值 | D11: 指标类型 | E11: 指标说明 | G11: 参考值
B12: 净现值 | C12: =现金流量明细表!C22 -> 0 | D12: 基础指标 | E12: 净现值指建设期及生产期各年净现金流量现值合计值，如果净现值为正，说明投资报酬率大于资本成本，该项目可以增加企业价值，反之则可能降低企业价值。 | G12: 项目净现值要求应大于0
B13: 净现值率 | C13: =现金流量明细表!C24/现金流量明细表!C20 -> #DIV/0! | D13: 基础指标 | E13: 净现值率指项目净现值与原始投入现值的比率，等于累计净现值/项目总投入现值*100%，单位投资现值所能带来的财务净现，财务净现值率约高，表明投资的单位效率越高。 | G13: 项目财务净现值率要求应大于0
B14: 内部收益率 | C14: =IRR(现金流量明细表!D10:O10) -> #NUM! | D14: 基础指标 | E14: 内部收益率又称内含报酬率，指资金流入现值总额与资金流出现值总额相等、净现值等于零时的折现率。如果内含报酬率高于资本成本，该项目可以为企业带来经济效益，反之则可能为企业带来亏损。 | G14: 项目内部收益率要求原则上不应低于8% | I14: 第一层找0对应的年份减1 | J14: 第二层找（0对应的年份减1）对应的累计现值的绝对值 | K14: 第三层找0对应的当年的值 | L14: 公式
B15: 动态回收期 | C15: =(HLOOKUP(0,现金流量明细表!$16:$28,ROW(现金流量明细表!E18)-ROW(现金流量明细表!E16)+1,FALSE)-1)+ABS(HLOOKUP((HLOOKUP(0,现金流量明细表!$16:$28,ROW(现金流量明细表!E18)-ROW(现金流量明细表!E16)+1,FALSE)-1),现金流量明细表!$18:$28,ROW(现金流量明细表!D24)-ROW(现金流量明细表!D18)+1,FALSE))/(HLOOKUP(0,现金流量明细表!$16:$28,ROW(现金流量明细表!D22)-ROW(现金流量明细表!E16)+1,FALSE)) -> #N/A | D15: 基础指标 | E15: 动态回收期指考虑资金的时间价值时收回初始投资所需的时间，回收年限越短，对项目而言越有利。 动态回收期=（累计净现金流量现值出现正值的年数-1）+上一年累计净现金流量现值的绝对值/出现正值年份净现金流量的现值。 | G15: 考虑资金时间价值时收回初始投资需要的时间。动态投资回收期应不高于5年（一般3年，且不超过项目合同期限） | I15: =(HLOOKUP(0,现金流量明细表!$16:$28,ROW(现金流量明细表!E18)-ROW(现金流量明细表!E16)+1,FALSE)-1) -> #N/A | J15: =ABS(HLOOKUP((HLOOKUP(0,现金流量明细表!$16:$28,ROW(现金流量明细表!E18)-ROW(现金流量明细表!E16)+1,FALSE)-1),现金流量明细表!$18:$28,ROW(现金流量明细表!D24)-ROW(现金流量明细表!D18)+1,FALSE)) -> #N/A | K15: =(HLOOKUP(0,现金流量明细表!$16:$28,ROW(现金流量明细表!D22)-ROW(现金流量明细表!E16)+1,FALSE)) -> #N/A | L15: =I15+J15/K15 -> #N/A
B16: 静态回收期 | C16: =(HLOOKUP(0,现金流量明细表!$17:$28,ROW(现金流量明细表!D18)-ROW(现金流量明细表!D17)+1,FALSE)-1)+ABS(HLOOKUP((HLOOKUP(0,现金流量明细表!$17:$28,ROW(现金流量明细表!E18)-ROW(现金流量明细表!E17)+1,FALSE)-1),现金流量明细表!$18:$28,ROW(现金流量明细表!D23)-ROW(现金流量明细表!D18)+1,FALSE))/(HLOOKUP(0,现金流量明细表!$17:$28,ROW(现金流量明细表!D21)-ROW(现金流量明细表!E17)+1,FALSE)) -> #N/A | D16: 基础指标 | E16: 静态回收期指不考虑资金的时间价值时收回初始投资所需的时间，回收年限越短，对项目而言越有利。 静态回收期=（累计净现金流量出现正值的年数-1）+上一年累计净现金流量的绝对值/出现正值年份净现金流量 | G16: 不考虑资金时间价值时收回初始投资需要的时间。静态投资回收期应不高于5年（一般3年，且不超过项目合同期限） | I16: =(HLOOKUP(0,现金流量明细表!$17:$28,ROW(现金流量明细表!D18)-ROW(现金流量明细表!D17)+1,FALSE)-1) -> #N/A | J16: =ABS(HLOOKUP((HLOOKUP(0,现金流量明细表!$17:$28,ROW(现金流量明细表!E18)-ROW(现金流量明细表!E17)+1,FALSE)-1),现金流量明细表!$18:$28,ROW(现金流量明细表!D23)-ROW(现金流量明细表!D18)+1,FALSE)) -> #N/A | K16: =(HLOOKUP(0,现金流量明细表!$17:$28,ROW(现金流量明细表!D21)-ROW(现金流量明细表!E17)+1,FALSE)) -> #N/A | L16: =I16+J16/K16 -> #N/A
B17: 项目整体毛利 | C17: =('收入支出明细表（基础数据表）'!T3-'收入支出明细表（基础数据表）'!T96-'收入支出明细表（基础数据表）'!T215) -> 0 | D17: 辅助指标 | E17: 利润指项目收入减去项目支出（含成本与投资）后的余额。 | G17: 结合实际情况和往年情况确定
B18: 项目整体利润率 | C18: =('收入支出明细表（基础数据表）'!T3-'收入支出明细表（基础数据表）'!T96-'收入支出明细表（基础数据表）'!T215)/'收入支出明细表（基础数据表）'!T3 -> #DIV/0! | D18: 辅助指标 | E18: 利润指项目收入减去项目支出（含成本与投资）后的余额。利润率是指利润与项目收入的比率。利润率越高，说明项目的盈利能力强。 | G18: 结合实际情况和往年情况确定
B19: IT部分毛利 | C19: =('收入支出明细表（基础数据表）'!T6-'收入支出明细表（基础数据表）'!T99-'收入支出明细表（基础数据表）'!T140) -> 0 | D19: 辅助指标 | E19: IT部分毛利指IT类项目收入减去IT类项目支出（含成本与投资）后的余额。 | G19: 结合实际情况和往年情况确定
B20: IT部分利润率 | C20: =('收入支出明细表（基础数据表）'!T6-'收入支出明细表（基础数据表）'!T99-'收入支出明细表（基础数据表）'!T140)/'收入支出明细表（基础数据表）'!T6 -> #DIV/0! | D20: 辅助指标 | E20: IT部分利润指IT类项目收入减去IT类项目支出（含成本与投资）后的余额。利润率是指利润与项目收入的比率。利润率越高，说明项目的盈利能力强。 | G20: 结合实际情况和往年情况确定
B22: 业务价值评估
B23: 评价指标 | C23: 指标说明 | E23: 指标达成情况描述
B24: 客户规模 | C24: 主要评价集团客户的级别，规模和影响力。
B25: 标杆效应及对CT拉动效应分析 | C25: 主要考核项目对于行业的影响作用；对CT拉动的影响作用。
B26: 政府重点建设项目 | C26: 主要考核政府对于项目的重视程度。
B27: 项目可能涉及5G应用场景的复制 | C27: 主要评价项目是否涉及5G应用场景，能否复制已有的应用场景，并对5G应用场景有其他方面的扩展。
B28: 对市场占有率的影响 | C28: 主要评价项目投资对于扩大市场占有率和影响力的带动作用。
B29: 其他业务价值 | C29: 如有其他业务价值，可视需求增加，请自行补充。

Sheet 收入支出明细表（基础数据表）
A1: 填写方式 | B1: 分年填写 | D1: ICT项目收入支出（基础数据表）
A2: 分类 | E2: 收入/支出具体内容 | F2: 增值税率 | G2: 金额（含税） | H2: 期初 | I2: 第1年 | J2: 第2年 | K2: 第3年 | L2: 第4年 | M2: 第5年 | N2: 第6年 | O2: 第7年 | P2: 第8年 | Q2: 第9年 | R2: 第10年 | S2: ... | T2: 金额（不含税） | U2: 第0年 | V2: 第1年 | W2: 第2年 | X2: 第3年 | Y2: 第4年 | Z2: 第5年 | AA2: 第6年 | AB2: 第7年 | AC2: 第8年 | AD2: 第9年 | AE2: 第10年 | AF2: ... | AG2: 指标说明
A3: 收入 | B3: 项目收入合计 | D3: 收入 | G3: =G6+G40 -> 0 | H3: =H6+H40 -> 0 | I3: =I6+I40 -> 0 | J3: =J6+J40 -> 0 | K3: =K6+K40 -> 0 | L3: =L6+L40 -> 0 | M3: =M6+M40 -> 0 | N3: =N6+N40 -> 0 | ... AF3: =AF6+AF40 -> 0
D4: 收款进度-金额 | G4: =G7+G41 -> 0 | H4: =H7+H41 -> 0 | I4: =I7+I41 -> 0 | J4: =J7+J41 -> 0 | K4: =K7+K41 -> 0 | L4: =L7+L41 -> 0 | M4: =M7+M41 -> 0 | N4: =N7+N41 -> 0 | ... AF4: =AF7+AF41 -> 0
D5: 收款进度-比例 | H5: =H4/$G4 -> #DIV/0! | I5: =I4/$G4 -> #DIV/0! | J5: =J4/$G4 -> #DIV/0! | K5: =K4/$G4 -> #DIV/0! | L5: =L4/$G4 -> #DIV/0! | M5: =M4/$G4 -> #DIV/0! | N5: =N4/$G4 -> #DIV/0! | O5: =O4/$G4 -> #DIV/0! | ... S5: =S4/$G4 -> #DIV/0!
B6: IT类收入 | C6: IT类收入合计 | D6: 收入 | G6: =SUM(G9+G27+G30+G33+G36) -> 0 | H6: =SUM(H9+H27+H30+H33+H36) -> 0 | I6: =SUM(I9+I27+I30+I33+I36) -> 0 | J6: =SUM(J9+J27+J30+J33+J36) -> 0 | K6: =SUM(K9+K27+K30+K33+K36) -> 0 | L6: =SUM(L9+L27+L30+L33+L36) -> 0 | M6: =SUM(M9+M27+M30+M33+M36) -> 0 | N6: =SUM(N9+N27+N30+N33+N36) -> 0 | ... AF6: =SUM(AF9+AF27+AF30+AF33+AF36) -> 0
D7: 收款进度-金额 | G7: =SUM(G10+G28+G31+G34+G37) -> 0 | H7: =SUM(H10+H28+H31+H34+H37) -> 0 | I7: =SUM(I10+I28+I31+I34+I37) -> 0 | J7: =SUM(J10+J28+J31+J34+J37) -> 0 | K7: =SUM(K10+K28+K31+K34+K37) -> 0 | L7: =SUM(L10+L28+L31+L34+L37) -> 0 | M7: =SUM(M10+M28+M31+M34+M37) -> 0 | N7: =SUM(N10+N28+N31+N34+N37) -> 0 | ... AF7: =SUM(AF10+AF28+AF31+AF34+AF37) -> 0
D8: 收款进度-比例 | H8: =H7/$G7 -> #DIV/0! | I8: =I7/$G7 -> #DIV/0! | J8: =J7/$G7 -> #DIV/0! | K8: =K7/$G7 -> #DIV/0! | L8: =L7/$G7 -> #DIV/0! | M8: =M7/$G7 -> #DIV/0! | N8: =N7/$G7 -> #DIV/0! | O8: =O7/$G7 -> #DIV/0! | ... S8: =S7/$G7 -> #DIV/0!
C9: 1、通信及信息服务收入合计 | D9: 收入 | F9: 0.06 | G9: =SUM(G12+G15+G18+G21+G24) -> 0 | H9: =SUM(H12+H15+H18+H21+H24) -> 0 | I9: =SUM(I12+I15+I18+I21+I24) -> 0 | J9: =SUM(J12+J15+J18+J21+J24) -> 0 | K9: =SUM(K12+K15+K18+K21+K24) -> 0 | L9: =SUM(L12+L15+L18+L21+L24) -> 0 | M9: =SUM(M12+M15+M18+M21+M24) -> 0 | N9: =SUM(N12+N15+N18+N21+N24) -> 0 | ... AF9: =SUM(AF12+AF15+AF18+AF21+AF24) -> 0
D10: 收款进度-金额 | G10: =SUM(G13+G16+G19+G22+G25) -> 0 | H10: =SUM(H13+H16+H19+H22+H25) -> 0 | I10: =SUM(I13+I16+I19+I22+I25) -> 0 | J10: =SUM(J13+J16+J19+J22+J25) -> 0 | K10: =SUM(K13+K16+K19+K22+K25) -> 0 | L10: =SUM(L13+L16+L19+L22+L25) -> 0 | M10: =SUM(M13+M16+M19+M22+M25) -> 0 | N10: =SUM(N13+N16+N19+N22+N25) -> 0 | ... S10: =SUM(S13+S16+S19+S22+S25) -> 0 | T10: =SUM(T13+T16+T19+T22) -> 0 | U10: =SUM(U13+U16+U19+U22) -> 0 | V10: =SUM(V13+V16+V19+V22) -> 0 | W10: =SUM(W13+W16+W19+W22) -> 0 | X10: =SUM(X13+X16+X19+X22) -> 0 | Y10: =SUM(Y13+Y16+Y19+Y22) -> 0 | Z10: =SUM(Z13+Z16+Z19+Z22) -> 0 | AA10: =SUM(AA13+AA16+AA19+AA22) -> 0 | ... AF10: =SUM(AF13+AF16+AF19+AF22) -> 0
D11: 收款进度-比例 | H11: =H10/$G10 -> #DIV/0! | I11: =I10/$G10 -> #DIV/0! | J11: =J10/$G10 -> #DIV/0! | K11: =K10/$G10 -> #DIV/0! | L11: =L10/$G10 -> #DIV/0! | M11: =M10/$G10 -> #DIV/0! | N11: =N10/$G10 -> #DIV/0! | O11: =O10/$G10 -> #DIV/0! | ... S11: =S10/$G10 -> #DIV/0!
C12: 1-1 集成收入-信息服务 | D12: 收入 | F12: 0.06 | G12: =SUM(H12:S12) -> 0 | T12: =SUM(U12:AF12) -> 0 | U12: =H12/(1+$F$12) -> 0 | V12: =I12/(1+$F$12) -> 0 | W12: =J12/(1+$F$12) -> 0 | X12: =K12/(1+$F$12) -> 0 | Y12: =L12/(1+$F$12) -> 0 | Z12: =M12/(1+$F$12) -> 0 | AA12: =N12/(1+$F$12) -> 0 | AB12: =O12/(1+$F$12) -> 0 | ... AF12: =S12/(1+$F$12) -> 0 | AG12: 根据客户的需求，将硬件、网络、数据库及相应的应用软件进行优化整合，提供全面系统解决方案而向客户收取的系统集成费，主要包括项目集成方案的咨询、设计、软硬件安装、通信工程服务、调测开通等项目实施服务费，为一次性费用。
D13: 收款进度-金额 | G13: =SUM(H13:S13) -> 0
D14: 收款进度-比例 | H14: =H13/$G13 -> #DIV/0! | I14: =I13/$G13 -> #DIV/0! | J14: =J13/$G13 -> #DIV/0! | K14: =K13/$G13 -> #DIV/0! | L14: =L13/$G13 -> #DIV/0! | M14: =M13/$G13 -> #DIV/0! | N14: =N13/$G13 -> #DIV/0! | O14: =O13/$G13 -> #DIV/0! | ... S14: =S13/$G13 -> #DIV/0!
C15: 1-2 集成收入-安装服务 | D15: 收入 | F15: 0.09 | G15: =SUM(H15:S15) -> 0 | T15: =SUM(U15:AF15) -> 0 | U15: =H15/(1+$F$15) -> 0 | V15: =I15/(1+$F$15) -> 0 | W15: =J15/(1+$F$15) -> 0 | X15: =K15/(1+$F$15) -> 0 | Y15: =L15/(1+$F$15) -> 0 | Z15: =M15/(1+$F$15) -> 0 | AA15: =N15/(1+$F$15) -> 0 | AB15: =O15/(1+$F$15) -> 0 | ... AF15: =S15/(1+$F$15) -> 0
D16: 收款进度-金额 | G16: =SUM(H16:S16) -> 0
D17: 收款进度-比例 | H17: =H16/$G16 -> #DIV/0! | I17: =I16/$G16 -> #DIV/0! | J17: =J16/$G16 -> #DIV/0! | K17: =K16/$G16 -> #DIV/0! | L17: =L16/$G16 -> #DIV/0! | M17: =M16/$G16 -> #DIV/0! | N17: =N16/$G16 -> #DIV/0! | O17: =O16/$G16 -> #DIV/0! | ... S17: =S16/$G16 -> #DIV/0!
C18: 1-3 维保收入-信息服务 | D18: 收入 | F18: 0.06 | G18: =SUM(H18:S18) -> 0 | T18: =SUM(U18:AF18) -> 0 | U18: =H18/(1+$F$18) -> 0 | V18: =I18/(1+$F$18) -> 0 | W18: =J18/(1+$F$18) -> 0 | X18: =K18/(1+$F$18) -> 0 | Y18: =L18/(1+$F$18) -> 0 | Z18: =M18/(1+$F$18) -> 0 | AA18: =N18/(1+$F$18) -> 0 | AB18: =O18/(1+$F$18) -> 0 | ... AF18: =S18/(1+$F$18) -> 0 | AG18: 公司在ICT项目建成后，因提供后续维护保障服务而向客户收取的IT支撑服务、软硬件及系统支撑等支撑和维保费。
D19: 收款进度-金额 | G19: =SUM(H19:S19) -> 0
D20: 收款进度-比例 | H20: =H19/$G19 -> #DIV/0! | I20: =I19/$G19 -> #DIV/0! | J20: =J19/$G19 -> #DIV/0! | K20: =K19/$G19 -> #DIV/0! | L20: =L19/$G19 -> #DIV/0! | M20: =M19/$G19 -> #DIV/0! | N20: =N19/$G19 -> #DIV/0! | O20: =O19/$G19 -> #DIV/0! | ... S20: =S19/$G19 -> #DIV/0!
C21: 1-4 维保收入-安装服务 | D21: 收入 | F21: 0.09 | G21: =SUM(H21:S21) -> 0 | T21: =SUM(U21:AF21) -> 0 | U21: =H21/(1+$F$21) -> 0 | V21: =I21/(1+$F$21) -> 0 | W21: =J21/(1+$F$21) -> 0 | X21: =K21/(1+$F$21) -> 0 | Y21: =L21/(1+$F$21) -> 0 | Z21: =M21/(1+$F$21) -> 0 | AA21: =N21/(1+$F$21) -> 0 | AB21: =O21/(1+$F$21) -> 0 | ... AF21: =S21/(1+$F$21) -> 0
D22: 收款进度-金额 | G22: =SUM(H22:S22) -> 0
D23: 收款进度-比例 | H23: =H22/$G22 -> #DIV/0! | I23: =I22/$G22 -> #DIV/0! | J23: =J22/$G22 -> #DIV/0! | K23: =K22/$G22 -> #DIV/0! | L23: =L22/$G22 -> #DIV/0! | M23: =M22/$G22 -> #DIV/0! | N23: =N22/$G22 -> #DIV/0! | O23: =O22/$G22 -> #DIV/0! | ... S23: =S22/$G22 -> #DIV/0!
C24: 1-5 维保收入-设备及其他硬件维修服务 | D24: 收入 | F24: 0.13 | G24: =SUM(H24:S24) -> 0 | T24: =SUM(U24:AF24) -> 0 | U24: =H24/(1+$F$24) -> 0 | V24: =I24/(1+$F$24) -> 0 | W24: =J24/(1+$F$24) -> 0 | X24: =K24/(1+$F$24) -> 0 | Y24: =L24/(1+$F$24) -> 0 | Z24: =M24/(1+$F$24) -> 0 | AA24: =N24/(1+$F$24) -> 0 | AB24: =O24/(1+$F$24) -> 0 | ... AF24: =S24/(1+$F$24) -> 0
D25: 收款进度-金额 | G25: =SUM(H25:S25) -> 0
D26: 收款进度-比例 | H26: =H25/$G25 -> #DIV/0! | I26: =I25/$G25 -> #DIV/0! | J26: =J25/$G25 -> #DIV/0! | K26: =K25/$G25 -> #DIV/0! | L26: =L25/$G25 -> #DIV/0! | M26: =M25/$G25 -> #DIV/0! | N26: =N25/$G25 -> #DIV/0! | O26: =O25/$G25 -> #DIV/0! | ... S26: =S25/$G25 -> #DIV/0!
C27: 2、商品销售收入 | D27: 收入 | F27: 0.13 | G27: =SUM(H27:S27) -> 0 | T27: =SUM(U27:AF27) -> 0 | U27: =H27/(1+$F$27) -> 0 | V27: =I27/(1+$F$27) -> 0 | W27: =J27/(1+$F$27) -> 0 | X27: =K27/(1+$F$27) -> 0 | Y27: =L27/(1+$F$27) -> 0 | Z27: =M27/(1+$F$27) -> 0 | AA27: =N27/(1+$F$27) -> 0 | AB27: =O27/(1+$F$27) -> 0 | ... AF27: =S27/(1+$F$27) -> 0 | AG27: 销售ICT设备/终端/软件产生的收入。
D28: 收款进度-金额 | G28: =SUM(H28:S28) -> 0
D29: 收款进度-比例 | H29: =H28/$G28 -> #DIV/0! | I29: =I28/$G28 -> #DIV/0! | J29: =J28/$G28 -> #DIV/0! | K29: =K28/$G28 -> #DIV/0! | L29: =L28/$G28 -> #DIV/0! | M29: =M28/$G28 -> #DIV/0! | N29: =N28/$G28 -> #DIV/0! | O29: =O28/$G28 -> #DIV/0! | ... S29: =S28/$G28 -> #DIV/0!
C30: 3、ICT设备/终端租赁收入 | D30: 收入 | F30: 0.13 | G30: =SUM(H30:S30) -> 0 | T30: =SUM(U30:AF30) -> 0 | U30: =H30/(1+$F$30) -> 0 | V30: =I30/(1+$F$30) -> 0 | W30: =J30/(1+$F$30) -> 0 | X30: =K30/(1+$F$30) -> 0 | Y30: =L30/(1+$F$30) -> 0 | Z30: =M30/(1+$F$30) -> 0 | AA30: =N30/(1+$F$30) -> 0 | AB30: =O30/(1+$F$30) -> 0 | ... AF30: =S30/(1+$F$30) -> 0 | AG30: 出租ICT设备/终端产生的收入。
D31: 收款进度-金额 | G31: =SUM(H31:S31) -> 0
D32: 收款进度-比例 | H32: =H31/$G31 -> #DIV/0! | I32: =I31/$G31 -> #DIV/0! | J32: =J31/$G31 -> #DIV/0! | K32: =K31/$G31 -> #DIV/0! | L32: =L31/$G31 -> #DIV/0! | M32: =M31/$G31 -> #DIV/0! | N32: =N31/$G31 -> #DIV/0! | O32: =O31/$G31 -> #DIV/0! | ... S32: =S31/$G31 -> #DIV/0!
C33: 4、ICT设备/终端转租收入 | D33: 收入 | F33: 0.13 | G33: =SUM(H33:S33) -> 0 | T33: =SUM(U33:AF33) -> 0 | U33: =H33/(1+$F$33) -> 0 | V33: =I33/(1+$F$33) -> 0 | W33: =J33/(1+$F$33) -> 0 | X33: =K33/(1+$F$33) -> 0 | Y33: =L33/(1+$F$33) -> 0 | Z33: =M33/(1+$F$33) -> 0 | AA33: =N33/(1+$F$33) -> 0 | AB33: =O33/(1+$F$33) -> 0 | ... AF33: =S33/(1+$F$33) -> 0 | AG33: 转租ICT设备/终端产生的租赁收入。
D34: 收款进度-金额 | G34: =SUM(H34:S34) -> 0
D35: 收款进度-比例 | H35: =H34/$G34 -> #DIV/0! | I35: =I34/$G34 -> #DIV/0! | J35: =J34/$G34 -> #DIV/0! | K35: =K34/$G34 -> #DIV/0! | L35: =L34/$G34 -> #DIV/0! | M35: =M34/$G34 -> #DIV/0! | N35: =N34/$G34 -> #DIV/0! | O35: =O34/$G34 -> #DIV/0! | ... S35: =S34/$G34 -> #DIV/0!
C36: 5、工程建设与服务收入 | D36: 收入 | F36: 0.09 | G36: =SUM(H36:S36) -> 0 | T36: =SUM(U36:AF36) -> 0 | U36: =H36/(1+$F$36) -> 0 | V36: =I36/(1+$F$36) -> 0 | W36: =J36/(1+$F$36) -> 0 | X36: =K36/(1+$F$36) -> 0 | Y36: =L36/(1+$F$36) -> 0 | Z36: =M36/(1+$F$36) -> 0 | AA36: =N36/(1+$F$36) -> 0 | AB36: =O36/(1+$F$36) -> 0 | ... AF36: =S36/(1+$F$36) -> 0 | AG36: 公司作为代理人，提供工程代办服务收取的代办管理费等收入或作为主要责任人提供工程服务产生的收入。
D37: 收款进度-金额 | G37: =SUM(H37:S37) -> 0
D38: 收款进度-比例 | H38: =H37/$G37 -> #DIV/0! | I38: =I37/$G37 -> #DIV/0! | J38: =J37/$G37 -> #DIV/0! | K38: =K37/$G37 -> #DIV/0! | L38: =L37/$G37 -> #DIV/0! | M38: =M37/$G37 -> #DIV/0! | N38: =N37/$G37 -> #DIV/0! | O38: =O37/$G37 -> #DIV/0! | ... S38: =S37/$G37 -> #DIV/0!
C39: …… | T39: =SUM(U39:AF39) -> 0 | U39: =H39/(1+$F$39) -> 0 | V39: =I39/(1+$F$39) -> 0 | W39: =J39/(1+$F$39) -> 0 | X39: =K39/(1+$F$39) -> 0 | Y39: =L39/(1+$F$39) -> 0 | Z39: =M39/(1+$F$39) -> 0 | AA39: =N39/(1+$F$39) -> 0 | AB39: =O39/(1+$F$39) -> 0 | ... AF39: =S39/(1+$F$39) -> 0 | AG39: 除上述5项外的其他IT类收入，如有多个，可插行填写
B40: CT类收入 | C40: CT类收入合计 | D40: 收入 | G40: =G43+G61 -> 0 | H40: =H43+H61 -> 0 | I40: =I43+I61 -> 0 | J40: =J43+J61 -> 0 | K40: =K43+K61 -> 0 | L40: =L43+L61 -> 0 | M40: =M43+M61 -> 0 | N40: =N43+N61 -> 0 | ... AF40: =AF43+AF61 -> 0
...

Sheet 收入支出明细表（含税）
A1: ICT项目收入支出（含税）
A2: 分类 | E2: 收入/支出具体内容 | F2: 增值税率 | G2: 金额（含税） | H2: 期初 | I2: 第1年 | J2: 第2年 | K2: 第3年 | L2: 第4年 | M2: 第5年 | N2: 第6年 | O2: 第7年 | P2: 第8年 | Q2: 第9年 | R2: 第10年 | S2: ...
A3: 收入 | B3: 项目收入合计 | D3: 收入 | E3: ='收入支出明细表（基础数据表）'!E3 -> 0 | F3: ='收入支出明细表（基础数据表）'!F3 -> 0 | G3: ='收入支出明细表（基础数据表）'!G3 -> 0 | H3: ='收入支出明细表（基础数据表）'!H3 -> 0 | I3: ='收入支出明细表（基础数据表）'!I3 -> 0 | J3: ='收入支出明细表（基础数据表）'!J3 -> 0 | K3: ='收入支出明细表（基础数据表）'!K3 -> 0 | L3: ='收入支出明细表（基础数据表）'!L3 -> 0 | ... S3: ='收入支出明细表（基础数据表）'!S3 -> 0
D4: 收款进度-金额 | E4: ='收入支出明细表（基础数据表）'!E4 -> 0 | F4: ='收入支出明细表（基础数据表）'!F4 -> 0 | G4: ='收入支出明细表（基础数据表）'!G4 -> 0 | H4: ='收入支出明细表（基础数据表）'!H4 -> 0 | I4: ='收入支出明细表（基础数据表）'!I4 -> 0 | J4: ='收入支出明细表（基础数据表）'!J4 -> 0 | K4: ='收入支出明细表（基础数据表）'!K4 -> 0 | L4: ='收入支出明细表（基础数据表）'!L4 -> 0 | ... S4: ='收入支出明细表（基础数据表）'!S4 -> 0
D5: 收款进度-比例 | E5: ='收入支出明细表（基础数据表）'!E5 -> 0 | F5: ='收入支出明细表（基础数据表）'!F5 -> 0 | G5: ='收入支出明细表（基础数据表）'!G5 -> 0 | H5: ='收入支出明细表（基础数据表）'!H5 -> #DIV/0! | I5: ='收入支出明细表（基础数据表）'!I5 -> #DIV/0! | J5: ='收入支出明细表（基础数据表）'!J5 -> #DIV/0! | K5: ='收入支出明细表（基础数据表）'!K5 -> #DIV/0! | L5: ='收入支出明细表（基础数据表）'!L5 -> #DIV/0! | ... S5: ='收入支出明细表（基础数据表）'!S5 -> #DIV/0!
B6: IT类收入 | C6: IT类收入合计 | D6: 收入 | E6: ='收入支出明细表（基础数据表）'!E6 -> 0 | F6: ='收入支出明细表（基础数据表）'!F6 -> 0 | G6: ='收入支出明细表（基础数据表）'!G6 -> 0 | H6: ='收入支出明细表（基础数据表）'!H6 -> 0 | I6: ='收入支出明细表（基础数据表）'!I6 -> 0 | J6: ='收入支出明细表（基础数据表）'!J6 -> 0 | K6: ='收入支出明细表（基础数据表）'!K6 -> 0 | L6: ='收入支出明细表（基础数据表）'!L6 -> 0 | ... S6: ='收入支出明细表（基础数据表）'!S6 -> 0
D7: 收款进度-金额 | E7: ='收入支出明细表（基础数据表）'!E7 -> 0 | F7: ='收入支出明细表（基础数据表）'!F7 -> 0 | G7: ='收入支出明细表（基础数据表）'!G7 -> 0 | H7: ='收入支出明细表（基础数据表）'!H7 -> 0 | I7: ='收入支出明细表（基础数据表）'!I7 -> 0 | J7: ='收入支出明细表（基础数据表）'!J7 -> 0 | K7: ='收入支出明细表（基础数据表）'!K7 -> 0 | L7: ='收入支出明细表（基础数据表）'!L7 -> 0 | ... S7: ='收入支出明细表（基础数据表）'!S7 -> 0
D8: 收款进度-比例 | E8: ='收入支出明细表（基础数据表）'!E8 -> 0 | F8: ='收入支出明细表（基础数据表）'!F8 -> 0 | G8: ='收入支出明细表（基础数据表）'!G8 -> 0 | H8: ='收入支出明细表（基础数据表）'!H8 -> #DIV/0! | I8: ='收入支出明细表（基础数据表）'!I8 -> #DIV/0! | J8: ='收入支出明细表（基础数据表）'!J8 -> #DIV/0! | K8: ='收入支出明细表（基础数据表）'!K8 -> #DIV/0! | L8: ='收入支出明细表（基础数据表）'!L8 -> #DIV/0! | ... S8: ='收入支出明细表（基础数据表）'!S8 -> #DIV/0!
C9: 1、通信及信息服务收入合计 | D9: 收入 | E9: ='收入支出明细表（基础数据表）'!E9 -> 0 | F9: ='收入支出明细表（基础数据表）'!F9 -> 0.06 | G9: ='收入支出明细表（基础数据表）'!G9 -> 0 | H9: ='收入支出明细表（基础数据表）'!H9 -> 0 | I9: ='收入支出明细表（基础数据表）'!I9 -> 0 | J9: ='收入支出明细表（基础数据表）'!J9 -> 0 | K9: ='收入支出明细表（基础数据表）'!K9 -> 0 | L9: ='收入支出明细表（基础数据表）'!L9 -> 0 | ... S9: ='收入支出明细表（基础数据表）'!S9 -> 0
D10: 收款进度-金额 | E10: ='收入支出明细表（基础数据表）'!E10 -> 0 | F10: ='收入支出明细表（基础数据表）'!F10 -> 0 | G10: ='收入支出明细表（基础数据表）'!G10 -> 0 | H10: ='收入支出明细表（基础数据表）'!H10 -> 0 | I10: ='收入支出明细表（基础数据表）'!I10 -> 0 | J10: ='收入支出明细表（基础数据表）'!J10 -> 0 | K10: ='收入支出明细表（基础数据表）'!K10 -> 0 | L10: ='收入支出明细表（基础数据表）'!L10 -> 0 | ... S10: ='收入支出明细表（基础数据表）'!S10 -> 0
D11: 收款进度-比例 | E11: ='收入支出明细表（基础数据表）'!E11 -> 0 | F11: ='收入支出明细表（基础数据表）'!F11 -> 0 | G11: ='收入支出明细表（基础数据表）'!G11 -> 0 | H11: ='收入支出明细表（基础数据表）'!H11 -> #DIV/0! | I11: ='收入支出明细表（基础数据表）'!I11 -> #DIV/0! | J11: ='收入支出明细表（基础数据表）'!J11 -> #DIV/0! | K11: ='收入支出明细表（基础数据表）'!K11 -> #DIV/0! | L11: ='收入支出明细表（基础数据表）'!L11 -> #DIV/0! | ... S11: ='收入支出明细表（基础数据表）'!S11 -> #DIV/0!
C12: 1-1 集成收入-信息服务 | D12: 收入 | E12: ='收入支出明细表（基础数据表）'!E12 -> 0 | F12: ='收入支出明细表（基础数据表）'!F12 -> 0.06 | G12: ='收入支出明细表（基础数据表）'!G12 -> 0 | H12: ='收入支出明细表（基础数据表）'!H12 -> 0 | I12: ='收入支出明细表（基础数据表）'!I12 -> 0 | J12: ='收入支出明细表（基础数据表）'!J12 -> 0 | K12: ='收入支出明细表（基础数据表）'!K12 -> 0 | L12: ='收入支出明细表（基础数据表）'!L12 -> 0 | ... S12: ='收入支出明细表（基础数据表）'!S12 -> 0
D13: 收款进度-金额 | E13: ='收入支出明细表（基础数据表）'!E13 -> 0 | F13: ='收入支出明细表（基础数据表）'!F13 -> 0 | G13: ='收入支出明细表（基础数据表）'!G13 -> 0 | H13: ='收入支出明细表（基础数据表）'!H13 -> 0 | I13: ='收入支出明细表（基础数据表）'!I13 -> 0 | J13: ='收入支出明细表（基础数据表）'!J13 -> 0 | K13: ='收入支出明细表（基础数据表）'!K13 -> 0 | L13: ='收入支出明细表（基础数据表）'!L13 -> 0 | ... S13: ='收入支出明细表（基础数据表）'!S13 -> 0
D14: 收款进度-比例 | E14: ='收入支出明细表（基础数据表）'!E14 -> 0 | F14: ='收入支出明细表（基础数据表）'!F14 -> 0 | G14: ='收入支出明细表（基础数据表）'!G14 -> 0 | H14: ='收入支出明细表（基础数据表）'!H14 -> #DIV/0! | I14: ='收入支出明细表（基础数据表）'!I14 -> #DIV/0! | J14: ='收入支出明细表（基础数据表）'!J14 -> #DIV/0! | K14: ='收入支出明细表（基础数据表）'!K14 -> #DIV/0! | L14: ='收入支出明细表（基础数据表）'!L14 -> #DIV/0! | ... S14: ='收入支出明细表（基础数据表）'!S14 -> #DIV/0!
C15: 1-2 集成收入-安装服务 | D15: 收入 | E15: ='收入支出明细表（基础数据表）'!E15 -> 0 | F15: ='收入支出明细表（基础数据表）'!F15 -> 0.09 | G15: ='收入支出明细表（基础数据表）'!G15 -> 0 | H15: ='收入支出明细表（基础数据表）'!H15 -> 0 | I15: ='收入支出明细表（基础数据表）'!I15 -> 0 | J15: ='收入支出明细表（基础数据表）'!J15 -> 0 | K15: ='收入支出明细表（基础数据表）'!K15 -> 0 | L15: ='收入支出明细表（基础数据表）'!L15 -> 0 | ... S15: ='收入支出明细表（基础数据表）'!S15 -> 0
D16: 收款进度-金额 | E16: ='收入支出明细表（基础数据表）'!E16 -> 0 | F16: ='收入支出明细表（基础数据表）'!F16 -> 0 | G16: ='收入支出明细表（基础数据表）'!G16 -> 0 | H16: ='收入支出明细表（基础数据表）'!H16 -> 0 | I16: ='收入支出明细表（基础数据表）'!I16 -> 0 | J16: ='收入支出明细表（基础数据表）'!J16 -> 0 | K16: ='收入支出明细表（基础数据表）'!K16 -> 0 | L16: ='收入支出明细表（基础数据表）'!L16 -> 0 | ... S16: ='收入支出明细表（基础数据表）'!S16 -> 0
D17: 收款进度-比例 | E17: ='收入支出明细表（基础数据表）'!E17 -> 0 | F17: ='收入支出明细表（基础数据表）'!F17 -> 0 | G17: ='收入支出明细表（基础数据表）'!G17 -> 0 | H17: ='收入支出明细表（基础数据表）'!H17 -> #DIV/0! | I17: ='收入支出明细表（基础数据表）'!I17 -> #DIV/0! | J17: ='收入支出明细表（基础数据表）'!J17 -> #DIV/0! | K17: ='收入支出明细表（基础数据表）'!K17 -> #DIV/0! | L17: ='收入支出明细表（基础数据表）'!L17 -> #DIV/0! | ... S17: ='收入支出明细表（基础数据表）'!S17 -> #DIV/0!
C18: 1-3 维保收入-信息服务 | D18: 收入 | E18: ='收入支出明细表（基础数据表）'!E18 -> 0 | F18: ='收入支出明细表（基础数据表）'!F18 -> 0.06 | G18: ='收入支出明细表（基础数据表）'!G18 -> 0 | H18: ='收入支出明细表（基础数据表）'!H18 -> 0 | I18: ='收入支出明细表（基础数据表）'!I18 -> 0 | J18: ='收入支出明细表（基础数据表）'!J18 -> 0 | K18: ='收入支出明细表（基础数据表）'!K18 -> 0 | L18: ='收入支出明细表（基础数据表）'!L18 -> 0 | ... S18: ='收入支出明细表（基础数据表）'!S18 -> 0
D19: 收款进度-金额 | E19: ='收入支出明细表（基础数据表）'!E19 -> 0 | F19: ='收入支出明细表（基础数据表）'!F19 -> 0 | G19: ='收入支出明细表（基础数据表）'!G19 -> 0 | H19: ='收入支出明细表（基础数据表）'!H19 -> 0 | I19: ='收入支出明细表（基础数据表）'!I19 -> 0 | J19: ='收入支出明细表（基础数据表）'!J19 -> 0 | K19: ='收入支出明细表（基础数据表）'!K19 -> 0 | L19: ='收入支出明细表（基础数据表）'!L19 -> 0 | ... S19: ='收入支出明细表（基础数据表）'!S19 -> 0
D20: 收款进度-比例 | E20: ='收入支出明细表（基础数据表）'!E20 -> 0 | F20: ='收入支出明细表（基础数据表）'!F20 -> 0 | G20: ='收入支出明细表（基础数据表）'!G20 -> 0 | H20: ='收入支出明细表（基础数据表）'!H20 -> #DIV/0! | I20: ='收入支出明细表（基础数据表）'!I20 -> #DIV/0! | J20: ='收入支出明细表（基础数据表）'!J20 -> #DIV/0! | K20: ='收入支出明细表（基础数据表）'!K20 -> #DIV/0! | L20: ='收入支出明细表（基础数据表）'!L20 -> #DIV/0! | ... S20: ='收入支出明细表（基础数据表）'!S20 -> #DIV/0!
C21: 1-4 维保收入-安装服务 | D21: 收入 | E21: ='收入支出明细表（基础数据表）'!E21 -> 0 | F21: ='收入支出明细表（基础数据表）'!F21 -> 0.09 | G21: ='收入支出明细表（基础数据表）'!G21 -> 0 | H21: ='收入支出明细表（基础数据表）'!H21 -> 0 | I21: ='收入支出明细表（基础数据表）'!I21 -> 0 | J21: ='收入支出明细表（基础数据表）'!J21 -> 0 | K21: ='收入支出明细表（基础数据表）'!K21 -> 0 | L21: ='收入支出明细表（基础数据表）'!L21 -> 0 | ... S21: ='收入支出明细表（基础数据表）'!S21 -> 0
D22: 收款进度-金额 | E22: ='收入支出明细表（基础数据表）'!E22 -> 0 | F22: ='收入支出明细表（基础数据表）'!F22 -> 0 | G22: ='收入支出明细表（基础数据表）'!G22 -> 0 | H22: ='收入支出明细表（基础数据表）'!H22 -> 0 | I22: ='收入支出明细表（基础数据表）'!I22 -> 0 | J22: ='收入支出明细表（基础数据表）'!J22 -> 0 | K22: ='收入支出明细表（基础数据表）'!K22 -> 0 | L22: ='收入支出明细表（基础数据表）'!L22 -> 0 | ... S22: ='收入支出明细表（基础数据表）'!S22 -> 0
D23: 收款进度-比例 | E23: ='收入支出明细表（基础数据表）'!E23 -> 0 | F23: ='收入支出明细表（基础数据表）'!F23 -> 0 | G23: ='收入支出明细表（基础数据表）'!G23 -> 0 | H23: ='收入支出明细表（基础数据表）'!H23 -> #DIV/0! | I23: ='收入支出明细表（基础数据表）'!I23 -> #DIV/0! | J23: ='收入支出明细表（基础数据表）'!J23 -> #DIV/0! | K23: ='收入支出明细表（基础数据表）'!K23 -> #DIV/0! | L23: ='收入支出明细表（基础数据表）'!L23 -> #DIV/0! | ... S23: ='收入支出明细表（基础数据表）'!S23 -> #DIV/0!
C24: 1-5 维保收入-设备及其他硬件维修服务 | D24: 收入 | E24: ='收入支出明细表（基础数据表）'!E24 -> 0 | F24: ='收入支出明细表（基础数据表）'!F24 -> 0.13 | G24: ='收入支出明细表（基础数据表）'!G24 -> 0 | H24: ='收入支出明细表（基础数据表）'!H24 -> 0 | I24: ='收入支出明细表（基础数据表）'!I24 -> 0 | J24: ='收入支出明细表（基础数据表）'!J24 -> 0 | K24: ='收入支出明细表（基础数据表）'!K24 -> 0 | L24: ='收入支出明细表（基础数据表）'!L24 -> 0 | ... S24: ='收入支出明细表（基础数据表）'!S24 -> 0
D25: 收款进度-金额 | E25: ='收入支出明细表（基础数据表）'!E25 -> 0 | F25: ='收入支出明细表（基础数据表）'!F25 -> 0 | G25: ='收入支出明细表（基础数据表）'!G25 -> 0 | H25: ='收入支出明细表（基础数据表）'!H25 -> 0 | I25: ='收入支出明细表（基础数据表）'!I25 -> 0 | J25: ='收入支出明细表（基础数据表）'!J25 -> 0 | K25: ='收入支出明细表（基础数据表）'!K25 -> 0 | L25: ='收入支出明细表（基础数据表）'!L25 -> 0 | ... S25: ='收入支出明细表（基础数据表）'!S25 -> 0
D26: 收款进度-比例 | E26: ='收入支出明细表（基础数据表）'!E26 -> 0 | F26: ='收入支出明细表（基础数据表）'!F26 -> 0 | G26: ='收入支出明细表（基础数据表）'!G26 -> 0 | H26: ='收入支出明细表（基础数据表）'!H26 -> #DIV/0! | I26: ='收入支出明细表（基础数据表）'!I26 -> #DIV/0! | J26: ='收入支出明细表（基础数据表）'!J26 -> #DIV/0! | K26: ='收入支出明细表（基础数据表）'!K26 -> #DIV/0! | L26: ='收入支出明细表（基础数据表）'!L26 -> #DIV/0! | ... S26: ='收入支出明细表（基础数据表）'!S26 -> #DIV/0!
C27: 2、商品销售收入 | D27: 收入 | E27: ='收入支出明细表（基础数据表）'!E27 -> 0 | F27: ='收入支出明细表（基础数据表）'!F27 -> 0.13 | G27: ='收入支出明细表（基础数据表）'!G27 -> 0 | H27: ='收入支出明细表（基础数据表）'!H27 -> 0 | I27: ='收入支出明细表（基础数据表）'!I27 -> 0 | J27: ='收入支出明细表（基础数据表）'!J27 -> 0 | K27: ='收入支出明细表（基础数据表）'!K27 -> 0 | L27: ='收入支出明细表（基础数据表）'!L27 -> 0 | ... S27: ='收入支出明细表（基础数据表）'!S27 -> 0
D28: 收款进度-金额 | E28: ='收入支出明细表（基础数据表）'!E28 -> 0 | F28: ='收入支出明细表（基础数据表）'!F28 -> 0 | G28: ='收入支出明细表（基础数据表）'!G28 -> 0 | H28: ='收入支出明细表（基础数据表）'!H28 -> 0 | I28: ='收入支出明细表（基础数据表）'!I28 -> 0 | J28: ='收入支出明细表（基础数据表）'!J28 -> 0 | K28: ='收入支出明细表（基础数据表）'!K28 -> 0 | L28: ='收入支出明细表（基础数据表）'!L28 -> 0 | ... S28: ='收入支出明细表（基础数据表）'!S28 -> 0
D29: 收款进度-比例 | E29: ='收入支出明细表（基础数据表）'!E29 -> 0 | F29: ='收入支出明细表（基础数据表）'!F29 -> 0 | G29: ='收入支出明细表（基础数据表）'!G29 -> 0 | H29: ='收入支出明细表（基础数据表）'!H29 -> #DIV/0! | I29: ='收入支出明细表（基础数据表）'!I29 -> #DIV/0! | J29: ='收入支出明细表（基础数据表）'!J29 -> #DIV/0! | K29: ='收入支出明细表（基础数据表）'!K29 -> #DIV/0! | L29: ='收入支出明细表（基础数据表）'!L29 -> #DIV/0! | ... S29: ='收入支出明细表（基础数据表）'!S29 -> #DIV/0!
C30: 3、ICT设备/终端租赁收入 | D30: 收入 | E30: ='收入支出明细表（基础数据表）'!E30 -> 0 | F30: ='收入支出明细表（基础数据表）'!F30 -> 0.13 | G30: ='收入支出明细表（基础数据表）'!G30 -> 0 | H30: ='收入支出明细表（基础数据表）'!H30 -> 0 | I30: ='收入支出明细表（基础数据表）'!I30 -> 0 | J30: ='收入支出明细表（基础数据表）'!J30 -> 0 | K30: ='收入支出明细表（基础数据表）'!K30 -> 0 | L30: ='收入支出明细表（基础数据表）'!L30 -> 0 | ... S30: ='收入支出明细表（基础数据表）'!S30 -> 0
D31: 收款进度-金额 | E31: ='收入支出明细表（基础数据表）'!E31 -> 0 | F31: ='收入支出明细表（基础数据表）'!F31 -> 0 | G31: ='收入支出明细表（基础数据表）'!G31 -> 0 | H31: ='收入支出明细表（基础数据表）'!H31 -> 0 | I31: ='收入支出明细表（基础数据表）'!I31 -> 0 | J31: ='收入支出明细表（基础数据表）'!J31 -> 0 | K31: ='收入支出明细表（基础数据表）'!K31 -> 0 | L31: ='收入支出明细表（基础数据表）'!L31 -> 0 | ... S31: ='收入支出明细表（基础数据表）'!S31 -> 0
D32: 收款进度-比例 | E32: ='收入支出明细表（基础数据表）'!E32 -> 0 | F32: ='收入支出明细表（基础数据表）'!F32 -> 0 | G32: ='收入支出明细表（基础数据表）'!G32 -> 0 | H32: ='收入支出明细表（基础数据表）'!H32 -> #DIV/0! | I32: ='收入支出明细表（基础数据表）'!I32 -> #DIV/0! | J32: ='收入支出明细表（基础数据表）'!J32 -> #DIV/0! | K32: ='收入支出明细表（基础数据表）'!K32 -> #DIV/0! | L32: ='收入支出明细表（基础数据表）'!L32 -> #DIV/0! | ... S32: ='收入支出明细表（基础数据表）'!S32 -> #DIV/0!
C33: 4、ICT设备/终端转租收入 | D33: 收入 | E33: ='收入支出明细表（基础数据表）'!E33 -> 0 | F33: ='收入支出明细表（基础数据表）'!F33 -> 0.13 | G33: ='收入支出明细表（基础数据表）'!G33 -> 0 | H33: ='收入支出明细表（基础数据表）'!H33 -> 0 | I33: ='收入支出明细表（基础数据表）'!I33 -> 0 | J33: ='收入支出明细表（基础数据表）'!J33 -> 0 | K33: ='收入支出明细表（基础数据表）'!K33 -> 0 | L33: ='收入支出明细表（基础数据表）'!L33 -> 0 | ... S33: ='收入支出明细表（基础数据表）'!S33 -> 0
D34: 收款进度-金额 | E34: ='收入支出明细表（基础数据表）'!E34 -> 0 | F34: ='收入支出明细表（基础数据表）'!F34 -> 0 | G34: ='收入支出明细表（基础数据表）'!G34 -> 0 | H34: ='收入支出明细表（基础数据表）'!H34 -> 0 | I34: ='收入支出明细表（基础数据表）'!I34 -> 0 | J34: ='收入支出明细表（基础数据表）'!J34 -> 0 | K34: ='收入支出明细表（基础数据表）'!K34 -> 0 | L34: ='收入支出明细表（基础数据表）'!L34 -> 0 | ... S34: ='收入支出明细表（基础数据表）'!S34 -> 0
D35: 收款进度-比例 | E35: ='收入支出明细表（基础数据表）'!E35 -> 0 | F35: ='收入支出明细表（基础数据表）'!F35 -> 0 | G35: ='收入支出明细表（基础数据表）'!G35 -> 0 | H35: ='收入支出明细表（基础数据表）'!H35 -> #DIV/0! | I35: ='收入支出明细表（基础数据表）'!I35 -> #DIV/0! | J35: ='收入支出明细表（基础数据表）'!J35 -> #DIV/0! | K35: ='收入支出明细表（基础数据表）'!K35 -> #DIV/0! | L35: ='收入支出明细表（基础数据表）'!L35 -> #DIV/0! | ... S35: ='收入支出明细表（基础数据表）'!S35 -> #DIV/0!
C36: 5、工程建设与服务收入 | D36: 收入 | E36: ='收入支出明细表（基础数据表）'!E36 -> 0 | F36: ='收入支出明细表（基础数据表）'!F36 -> 0.09 | G36: ='收入支出明细表（基础数据表）'!G36 -> 0 | H36: ='收入支出明细表（基础数据表）'!H36 -> 0 | I36: ='收入支出明细表（基础数据表）'!I36 -> 0 | J36: ='收入支出明细表（基础数据表）'!J36 -> 0 | K36: ='收入支出明细表（基础数据表）'!K36 -> 0 | L36: ='收入支出明细表（基础数据表）'!L36 -> 0 | ... S36: ='收入支出明细表（基础数据表）'!S36 -> 0
D37: 收款进度-金额 | E37: ='收入支出明细表（基础数据表）'!E37 -> 0 | F37: ='收入支出明细表（基础数据表）'!F37 -> 0 | G37: ='收入支出明细表（基础数据表）'!G37 -> 0 | H37: ='收入支出明细表（基础数据表）'!H37 -> 0 | I37: ='收入支出明细表（基础数据表）'!I37 -> 0 | J37: ='收入支出明细表（基础数据表）'!J37 -> 0 | K37: ='收入支出明细表（基础数据表）'!K37 -> 0 | L37: ='收入支出明细表（基础数据表）'!L37 -> 0 | ... S37: ='收入支出明细表（基础数据表）'!S37 -> 0
D38: 收款进度-比例 | E38: ='收入支出明细表（基础数据表）'!E38 -> 0 | F38: ='收入支出明细表（基础数据表）'!F38 -> 0 | G38: ='收入支出明细表（基础数据表）'!G38 -> 0 | H38: ='收入支出明细表（基础数据表）'!H38 -> #DIV/0! | I38: ='收入支出明细表（基础数据表）'!I38 -> #DIV/0! | J38: ='收入支出明细表（基础数据表）'!J38 -> #DIV/0! | K38: ='收入支出明细表（基础数据表）'!K38 -> #DIV/0! | L38: ='收入支出明细表（基础数据表）'!L38 -> #DIV/0! | ... S38: ='收入支出明细表（基础数据表）'!S38 -> #DIV/0!
C39: …… | E39: ='收入支出明细表（基础数据表）'!E39 -> 0 | F39: ='收入支出明细表（基础数据表）'!F39 -> 0 | G39: ='收入支出明细表（基础数据表）'!G39 -> 0 | H39: ='收入支出明细表（基础数据表）'!H39 -> 0 | I39: ='收入支出明细表（基础数据表）'!I39 -> 0 | J39: ='收入支出明细表（基础数据表）'!J39 -> 0 | K39: ='收入支出明细表（基础数据表）'!K39 -> 0 | L39: ='收入支出明细表（基础数据表）'!L39 -> 0 | ... S39: ='收入支出明细表（基础数据表）'!S39 -> 0
B40: CT类收入 | C40: CT类收入合计 | D40: 收入 | E40: ='收入支出明细表（基础数据表）'!E40 -> 0 | F40: ='收入支出明细表（基础数据表）'!F40 -> 0 | G40: ='收入支出明细表（基础数据表）'!G40 -> 0 | H40: ='收入支出明细表（基础数据表）'!H40 -> 0 | I40: ='收入支出明细表（基础数据表）'!I40 -> 0 | J40: ='收入支出明细表（基础数据表）'!J40 -> 0 | K40: ='收入支出明细表（基础数据表）'!K40 -> 0 | L40: ='收入支出明细表（基础数据表）'!L40 -> 0 | ... S40: ='收入支出明细表（基础数据表）'!S40 -> 0
...

Sheet 收入支出明细表（不含税)
A1: ICT项目收入支出（不含税）
A2: 分类 | E2: 收入/支出具体内容 | F2: 增值税率 | G2: 金额（不含税） | H2: 期初 | I2: 第1年 | J2: 第2年 | K2: 第3年 | L2: 第4年 | M2: 第5年 | N2: 第6年 | O2: 第7年 | P2: 第8年 | Q2: 第9年 | R2: 第10年 | S2: ...
A3: 收入 | B3: 项目收入合计 | D3: 收入 | G3: ='收入支出明细表（基础数据表）'!T3 -> 0 | H3: ='收入支出明细表（基础数据表）'!U3 -> 0 | I3: ='收入支出明细表（基础数据表）'!V3 -> 0 | J3: ='收入支出明细表（基础数据表）'!W3 -> 0 | K3: ='收入支出明细表（基础数据表）'!X3 -> 0 | L3: ='收入支出明细表（基础数据表）'!Y3 -> 0 | M3: ='收入支出明细表（基础数据表）'!Z3 -> 0 | N3: ='收入支出明细表（基础数据表）'!AA3 -> 0 | ... S3: ='收入支出明细表（基础数据表）'!AF3 -> 0
B4: IT类收入 | C4: IT类收入合计 | D4: 收入 | G4: ='收入支出明细表（基础数据表）'!T6 -> 0 | H4: ='收入支出明细表（基础数据表）'!U6 -> 0 | I4: ='收入支出明细表（基础数据表）'!V6 -> 0 | J4: ='收入支出明细表（基础数据表）'!W6 -> 0 | K4: ='收入支出明细表（基础数据表）'!X6 -> 0 | L4: ='收入支出明细表（基础数据表）'!Y6 -> 0 | M4: ='收入支出明细表（基础数据表）'!Z6 -> 0 | N4: ='收入支出明细表（基础数据表）'!AA6 -> 0 | ... S4: ='收入支出明细表（基础数据表）'!AF6 -> 0
C5: 1、通信及信息服务收入合计 | D5: 收入 | F5: 0.06 | G5: ='收入支出明细表（基础数据表）'!T9 -> 0 | H5: ='收入支出明细表（基础数据表）'!U9 -> 0 | I5: ='收入支出明细表（基础数据表）'!V9 -> 0 | J5: ='收入支出明细表（基础数据表）'!W9 -> 0 | K5: ='收入支出明细表（基础数据表）'!X9 -> 0 | L5: ='收入支出明细表（基础数据表）'!Y9 -> 0 | M5: ='收入支出明细表（基础数据表）'!Z9 -> 0 | N5: ='收入支出明细表（基础数据表）'!AA9 -> 0 | ... S5: ='收入支出明细表（基础数据表）'!AF9 -> 0
C6: 1-1 集成收入-信息服务 | D6: 收入 | F6: 0.06 | G6: ='收入支出明细表（基础数据表）'!T12 -> 0 | H6: ='收入支出明细表（基础数据表）'!U12 -> 0 | I6: ='收入支出明细表（基础数据表）'!V12 -> 0 | J6: ='收入支出明细表（基础数据表）'!W12 -> 0 | K6: ='收入支出明细表（基础数据表）'!X12 -> 0 | L6: ='收入支出明细表（基础数据表）'!Y12 -> 0 | M6: ='收入支出明细表（基础数据表）'!Z12 -> 0 | N6: ='收入支出明细表（基础数据表）'!AA12 -> 0 | ... S6: ='收入支出明细表（基础数据表）'!AF12 -> 0
C7: 1-2 集成收入-安装服务 | D7: 收入 | F7: 0.09 | G7: ='收入支出明细表（基础数据表）'!T15 -> 0 | H7: ='收入支出明细表（基础数据表）'!U15 -> 0 | I7: ='收入支出明细表（基础数据表）'!V15 -> 0 | J7: ='收入支出明细表（基础数据表）'!W15 -> 0 | K7: ='收入支出明细表（基础数据表）'!X15 -> 0 | L7: ='收入支出明细表（基础数据表）'!Y15 -> 0 | M7: ='收入支出明细表（基础数据表）'!Z15 -> 0 | N7: ='收入支出明细表（基础数据表）'!AA15 -> 0 | ... S7: ='收入支出明细表（基础数据表）'!AF15 -> 0
C8: 1-3 维保收入-信息服务 | D8: 收入 | F8: 0.06 | G8: ='收入支出明细表（基础数据表）'!T18 -> 0 | H8: ='收入支出明细表（基础数据表）'!U18 -> 0 | I8: ='收入支出明细表（基础数据表）'!V18 -> 0 | J8: ='收入支出明细表（基础数据表）'!W18 -> 0 | K8: ='收入支出明细表（基础数据表）'!X18 -> 0 | L8: ='收入支出明细表（基础数据表）'!Y18 -> 0 | M8: ='收入支出明细表（基础数据表）'!Z18 -> 0 | N8: ='收入支出明细表（基础数据表）'!AA18 -> 0 | ... S8: ='收入支出明细表（基础数据表）'!AF18 -> 0
C9: 1-4 维保收入-安装服务 | D9: 收入 | F9: 0.09 | G9: ='收入支出明细表（基础数据表）'!T21 -> 0 | H9: ='收入支出明细表（基础数据表）'!U21 -> 0 | I9: ='收入支出明细表（基础数据表）'!V21 -> 0 | J9: ='收入支出明细表（基础数据表）'!W21 -> 0 | K9: ='收入支出明细表（基础数据表）'!X21 -> 0 | L9: ='收入支出明细表（基础数据表）'!Y21 -> 0 | M9: ='收入支出明细表（基础数据表）'!Z21 -> 0 | N9: ='收入支出明细表（基础数据表）'!AA21 -> 0 | ... S9: ='收入支出明细表（基础数据表）'!AF21 -> 0
C10: 1-5 维保收入-设备及其他硬件维修服务 | D10: 收入 | F10: 0.13 | G10: ='收入支出明细表（基础数据表）'!T24 -> 0 | H10: ='收入支出明细表（基础数据表）'!U24 -> 0 | I10: ='收入支出明细表（基础数据表）'!V24 -> 0 | J10: ='收入支出明细表（基础数据表）'!W24 -> 0 | K10: ='收入支出明细表（基础数据表）'!X24 -> 0 | L10: ='收入支出明细表（基础数据表）'!Y24 -> 0 | M10: ='收入支出明细表（基础数据表）'!Z24 -> 0 | N10: ='收入支出明细表（基础数据表）'!AA24 -> 0 | ... S10: ='收入支出明细表（基础数据表）'!AF24 -> 0
C11: 2、商品销售收入 | D11: 收入 | F11: 0.13 | G11: ='收入支出明细表（基础数据表）'!T27 -> 0 | H11: ='收入支出明细表（基础数据表）'!U27 -> 0 | I11: ='收入支出明细表（基础数据表）'!V27 -> 0 | J11: ='收入支出明细表（基础数据表）'!W27 -> 0 | K11: ='收入支出明细表（基础数据表）'!X27 -> 0 | L11: ='收入支出明细表（基础数据表）'!Y27 -> 0 | M11: ='收入支出明细表（基础数据表）'!Z27 -> 0 | N11: ='收入支出明细表（基础数据表）'!AA27 -> 0 | ... S11: ='收入支出明细表（基础数据表）'!AF27 -> 0
C12: 3、ICT设备/终端租赁收入 | D12: 收入 | F12: 0.13 | G12: ='收入支出明细表（基础数据表）'!T30 -> 0 | H12: ='收入支出明细表（基础数据表）'!U30 -> 0 | I12: ='收入支出明细表（基础数据表）'!V30 -> 0 | J12: ='收入支出明细表（基础数据表）'!W30 -> 0 | K12: ='收入支出明细表（基础数据表）'!X30 -> 0 | L12: ='收入支出明细表（基础数据表）'!Y30 -> 0 | M12: ='收入支出明细表（基础数据表）'!Z30 -> 0 | N12: ='收入支出明细表（基础数据表）'!AA30 -> 0 | ... S12: ='收入支出明细表（基础数据表）'!AF30 -> 0
C13: 4、ICT设备/终端转租收入 | D13: 收入 | F13: 0.13 | G13: ='收入支出明细表（基础数据表）'!T33 -> 0 | H13: ='收入支出明细表（基础数据表）'!U33 -> 0 | I13: ='收入支出明细表（基础数据表）'!V33 -> 0 | J13: ='收入支出明细表（基础数据表）'!W33 -> 0 | K13: ='收入支出明细表（基础数据表）'!X33 -> 0 | L13: ='收入支出明细表（基础数据表）'!Y33 -> 0 | M13: ='收入支出明细表（基础数据表）'!Z33 -> 0 | N13: ='收入支出明细表（基础数据表）'!AA33 -> 0 | ... S13: ='收入支出明细表（基础数据表）'!AF33 -> 0
C14: 5、工程建设与服务收入 | D14: 收入 | F14: 0.09 | G14: ='收入支出明细表（基础数据表）'!T36 -> 0 | H14: ='收入支出明细表（基础数据表）'!U36 -> 0 | I14: ='收入支出明细表（基础数据表）'!V36 -> 0 | J14: ='收入支出明细表（基础数据表）'!W36 -> 0 | K14: ='收入支出明细表（基础数据表）'!X36 -> 0 | L14: ='收入支出明细表（基础数据表）'!Y36 -> 0 | M14: ='收入支出明细表（基础数据表）'!Z36 -> 0 | N14: ='收入支出明细表（基础数据表）'!AA36 -> 0 | ... S14: ='收入支出明细表（基础数据表）'!AF36 -> 0
C15: …… | G15: ='收入支出明细表（基础数据表）'!T39 -> 0 | H15: ='收入支出明细表（基础数据表）'!U39 -> 0 | I15: ='收入支出明细表（基础数据表）'!V39 -> 0 | J15: ='收入支出明细表（基础数据表）'!W39 -> 0 | K15: ='收入支出明细表（基础数据表）'!X39 -> 0 | L15: ='收入支出明细表（基础数据表）'!Y39 -> 0 | M15: ='收入支出明细表（基础数据表）'!Z39 -> 0 | N15: ='收入支出明细表（基础数据表）'!AA39 -> 0 | ... S15: ='收入支出明细表（基础数据表）'!AF39 -> 0
B16: CT类收入 | C16: CT类收入合计 | D16: 收入 | G16: ='收入支出明细表（基础数据表）'!T40 -> 0 | H16: ='收入支出明细表（基础数据表）'!U40 -> 0 | I16: ='收入支出明细表（基础数据表）'!V40 -> 0 | J16: ='收入支出明细表（基础数据表）'!W40 -> 0 | K16: ='收入支出明细表（基础数据表）'!X40 -> 0 | L16: ='收入支出明细表（基础数据表）'!Y40 -> 0 | M16: ='收入支出明细表（基础数据表）'!Z40 -> 0 | N16: ='收入支出明细表（基础数据表）'!AA40 -> 0 | ... S16: ='收入支出明细表（基础数据表）'!AF40 -> 0
C17: 1、通信业务收入（基础电信服务） | D17: 收入 | G17: ='收入支出明细表（基础数据表）'!T43 -> 0 | H17: ='收入支出明细表（基础数据表）'!U43 -> 0 | I17: ='收入支出明细表（基础数据表）'!V43 -> 0 | J17: ='收入支出明细表（基础数据表）'!W43 -> 0 | K17: ='收入支出明细表（基础数据表）'!X43 -> 0 | L17: ='收入支出明细表（基础数据表）'!Y43 -> 0 | M17: ='收入支出明细表（基础数据表）'!Z43 -> 0 | N17: ='收入支出明细表（基础数据表）'!AA43 -> 0 | ... S17: ='收入支出明细表（基础数据表）'!AF43 -> 0
C18: 语音 | D18: 收入 | F18: 0.09 | G18: ='收入支出明细表（基础数据表）'!T46 -> 0 | H18: ='收入支出明细表（基础数据表）'!U46 -> 0 | I18: ='收入支出明细表（基础数据表）'!V46 -> 0 | J18: ='收入支出明细表（基础数据表）'!W46 -> 0 | K18: ='收入支出明细表（基础数据表）'!X46 -> 0 | L18: ='收入支出明细表（基础数据表）'!Y46 -> 0 | M18: ='收入支出明细表（基础数据表）'!Z46 -> 0 | N18: ='收入支出明细表（基础数据表）'!AA46 -> 0 | ... S18: ='收入支出明细表（基础数据表）'!AF46 -> 0
C19: 数据专线 | D19: 收入 | F19: 0.09 | G19: ='收入支出明细表（基础数据表）'!T49 -> 0 | H19: ='收入支出明细表（基础数据表）'!U49 -> 0 | I19: ='收入支出明细表（基础数据表）'!V49 -> 0 | J19: ='收入支出明细表（基础数据表）'!W49 -> 0 | K19: ='收入支出明细表（基础数据表）'!X49 -> 0 | L19: ='收入支出明细表（基础数据表）'!Y49 -> 0 | M19: ='收入支出明细表（基础数据表）'!Z49 -> 0 | N19: ='收入支出明细表（基础数据表）'!AA49 -> 0 | ... S19: ='收入支出明细表（基础数据表）'!AF49 -> 0
C20: IMS固话 | D20: 收入 | F20: 0.09 | G20: ='收入支出明细表（基础数据表）'!T52 -> 0 | H20: ='收入支出明细表（基础数据表）'!U52 -> 0 | I20: ='收入支出明细表（基础数据表）'!V52 -> 0 | J20: ='收入支出明细表（基础数据表）'!W52 -> 0 | K20: ='收入支出明细表（基础数据表）'!X52 -> 0 | L20: ='收入支出明细表（基础数据表）'!Y52 -> 0 | M20: ='收入支出明细表（基础数据表）'!Z52 -> 0 | N20: ='收入支出明细表（基础数据表）'!AA52 -> 0 | ... S20: ='收入支出明细表（基础数据表）'!AF52 -> 0
C21: 语音专线 | D21: 收入 | F21: 0.09 | G21: ='收入支出明细表（基础数据表）'!T55 -> 0 | H21: ='收入支出明细表（基础数据表）'!U55 -> 0 | I21: ='收入支出明细表（基础数据表）'!V55 -> 0 | J21: ='收入支出明细表（基础数据表）'!W55 -> 0 | K21: ='收入支出明细表（基础数据表）'!X55 -> 0 | L21: ='收入支出明细表（基础数据表）'!Y55 -> 0 | M21: ='收入支出明细表（基础数据表）'!Z55 -> 0 | N21: ='收入支出明细表（基础数据表）'!AA55 -> 0 | ... S21: ='收入支出明细表（基础数据表）'!AF55 -> 0
C22: …… | G22: ='收入支出明细表（基础数据表）'!T58 -> 0 | H22: ='收入支出明细表（基础数据表）'!U58 -> 0 | I22: ='收入支出明细表（基础数据表）'!V58 -> 0 | J22: ='收入支出明细表（基础数据表）'!W58 -> 0 | K22: ='收入支出明细表（基础数据表）'!X58 -> 0 | L22: ='收入支出明细表（基础数据表）'!Y58 -> 0 | M22: ='收入支出明细表（基础数据表）'!Z58 -> 0 | N22: ='收入支出明细表（基础数据表）'!AA58 -> 0 | ... S22: ='收入支出明细表（基础数据表）'!AF58 -> 0
G23: ='收入支出明细表（基础数据表）'!T59 -> 0 | H23: ='收入支出明细表（基础数据表）'!U59 -> 0 | I23: ='收入支出明细表（基础数据表）'!V59 -> 0 | J23: ='收入支出明细表（基础数据表）'!W59 -> 0 | K23: ='收入支出明细表（基础数据表）'!X59 -> 0 | L23: ='收入支出明细表（基础数据表）'!Y59 -> 0 | M23: ='收入支出明细表（基础数据表）'!Z59 -> 0 | N23: ='收入支出明细表（基础数据表）'!AA59 -> 0 | ... S23: ='收入支出明细表（基础数据表）'!AF59 -> 0
G24: ='收入支出明细表（基础数据表）'!T60 -> 0 | H24: ='收入支出明细表（基础数据表）'!U60 -> 0 | I24: ='收入支出明细表（基础数据表）'!V60 -> 0 | J24: ='收入支出明细表（基础数据表）'!W60 -> 0 | K24: ='收入支出明细表（基础数据表）'!X60 -> 0 | L24: ='收入支出明细表（基础数据表）'!Y60 -> 0 | M24: ='收入支出明细表（基础数据表）'!Z60 -> 0 | N24: ='收入支出明细表（基础数据表）'!AA60 -> 0 | ... S24: ='收入支出明细表（基础数据表）'!AF60 -> 0
C25: 2、通信业务收入（增值电信服务） | D25: 收入 | G25: ='收入支出明细表（基础数据表）'!T61 -> 0 | H25: ='收入支出明细表（基础数据表）'!U61 -> 0 | I25: ='收入支出明细表（基础数据表）'!V61 -> 0 | J25: ='收入支出明细表（基础数据表）'!W61 -> 0 | K25: ='收入支出明细表（基础数据表）'!X61 -> 0 | L25: ='收入支出明细表（基础数据表）'!Y61 -> 0 | M25: ='收入支出明细表（基础数据表）'!Z61 -> 0 | N25: ='收入支出明细表（基础数据表）'!AA61 -> 0 | ... S25: ='收入支出明细表（基础数据表）'!AF61 -> 0
C26: 短信 | D26: 收入 | F26: 0.06 | G26: ='收入支出明细表（基础数据表）'!T64 -> 0 | H26: ='收入支出明细表（基础数据表）'!U64 -> 0 | I26: ='收入支出明细表（基础数据表）'!V64 -> 0 | J26: ='收入支出明细表（基础数据表）'!W64 -> 0 | K26: ='收入支出明细表（基础数据表）'!X64 -> 0 | L26: ='收入支出明细表（基础数据表）'!Y64 -> 0 | M26: ='收入支出明细表（基础数据表）'!Z64 -> 0 | N26: ='收入支出明细表（基础数据表）'!AA64 -> 0 | ... S26: ='收入支出明细表（基础数据表）'!AF64 -> 0
C27: 数据流量 | D27: 收入 | F27: 0.06 | G27: ='收入支出明细表（基础数据表）'!T67 -> 0 | H27: ='收入支出明细表（基础数据表）'!U67 -> 0 | I27: ='收入支出明细表（基础数据表）'!V67 -> 0 | J27: ='收入支出明细表（基础数据表）'!W67 -> 0 | K27: ='收入支出明细表（基础数据表）'!X67 -> 0 | L27: ='收入支出明细表（基础数据表）'!Y67 -> 0 | M27: ='收入支出明细表（基础数据表）'!Z67 -> 0 | N27: ='收入支出明细表（基础数据表）'!AA67 -> 0 | ... S27: ='收入支出明细表（基础数据表）'!AF67 -> 0
C28: 企业宽带 | D28: 收入 | F28: 0.06 | G28: ='收入支出明细表（基础数据表）'!T70 -> 0 | H28: ='收入支出明细表（基础数据表）'!U70 -> 0 | I28: ='收入支出明细表（基础数据表）'!V70 -> 0 | J28: ='收入支出明细表（基础数据表）'!W70 -> 0 | K28: ='收入支出明细表（基础数据表）'!X70 -> 0 | L28: ='收入支出明细表（基础数据表）'!Y70 -> 0 | M28: ='收入支出明细表（基础数据表）'!Z70 -> 0 | N28: ='收入支出明细表（基础数据表）'!AA70 -> 0 | ... S28: ='收入支出明细表（基础数据表）'!AF70 -> 0
C29: 互联网专线 | D29: 收入 | F29: 0.06 | G29: ='收入支出明细表（基础数据表）'!T73 -> 0 | H29: ='收入支出明细表（基础数据表）'!U73 -> 0 | I29: ='收入支出明细表（基础数据表）'!V73 -> 0 | J29: ='收入支出明细表（基础数据表）'!W73 -> 0 | K29: ='收入支出明细表（基础数据表）'!X73 -> 0 | L29: ='收入支出明细表（基础数据表）'!Y73 -> 0 | M29: ='收入支出明细表（基础数据表）'!Z73 -> 0 | N29: ='收入支出明细表（基础数据表）'!AA73 -> 0 | ... S29: ='收入支出明细表（基础数据表）'!AF73 -> 0
C30: 云计算 | D30: 收入 | F30: 0.06 | G30: ='收入支出明细表（基础数据表）'!T76 -> 0 | H30: ='收入支出明细表（基础数据表）'!U76 -> 0 | I30: ='收入支出明细表（基础数据表）'!V76 -> 0 | J30: ='收入支出明细表（基础数据表）'!W76 -> 0 | K30: ='收入支出明细表（基础数据表）'!X76 -> 0 | L30: ='收入支出明细表（基础数据表）'!Y76 -> 0 | M30: ='收入支出明细表（基础数据表）'!Z76 -> 0 | N30: ='收入支出明细表（基础数据表）'!AA76 -> 0 | ... S30: ='收入支出明细表（基础数据表）'!AF76 -> 0
C31: 大数据 | D31: 收入 | F31: 0.06 | G31: ='收入支出明细表（基础数据表）'!T79 -> 0 | H31: ='收入支出明细表（基础数据表）'!U79 -> 0 | I31: ='收入支出明细表（基础数据表）'!V79 -> 0 | J31: ='收入支出明细表（基础数据表）'!W79 -> 0 | K31: ='收入支出明细表（基础数据表）'!X79 -> 0 | L31: ='收入支出明细表（基础数据表）'!Y79 -> 0 | M31: ='收入支出明细表（基础数据表）'!Z79 -> 0 | N31: ='收入支出明细表（基础数据表）'!AA79 -> 0 | ... S31: ='收入支出明细表（基础数据表）'!AF79 -> 0
C32: IDC | D32: 收入 | F32: 0.06 | G32: ='收入支出明细表（基础数据表）'!T82 -> 0 | H32: ='收入支出明细表（基础数据表）'!U82 -> 0 | I32: ='收入支出明细表（基础数据表）'!V82 -> 0 | J32: ='收入支出明细表（基础数据表）'!W82 -> 0 | K32: ='收入支出明细表（基础数据表）'!X82 -> 0 | L32: ='收入支出明细表（基础数据表）'!Y82 -> 0 | M32: ='收入支出明细表（基础数据表）'!Z82 -> 0 | N32: ='收入支出明细表（基础数据表）'!AA82 -> 0 | ... S32: ='收入支出明细表（基础数据表）'!AF82 -> 0
C33: 5G专网 | D33: 收入 | F33: 0.06 | G33: ='收入支出明细表（基础数据表）'!T85 -> 0 | H33: ='收入支出明细表（基础数据表）'!U85 -> 0 | I33: ='收入支出明细表（基础数据表）'!V85 -> 0 | J33: ='收入支出明细表（基础数据表）'!W85 -> 0 | K33: ='收入支出明细表（基础数据表）'!X85 -> 0 | L33: ='收入支出明细表（基础数据表）'!Y85 -> 0 | M33: ='收入支出明细表（基础数据表）'!Z85 -> 0 | N33: ='收入支出明细表（基础数据表）'!AA85 -> 0 | ... S33: ='收入支出明细表（基础数据表）'!AF85 -> 0
C34: 物联网 | D34: 收入 | F34: 0.06 | G34: ='收入支出明细表（基础数据表）'!T88 -> 0 | H34: ='收入支出明细表（基础数据表）'!U88 -> 0 | I34: ='收入支出明细表（基础数据表）'!V88 -> 0 | J34: ='收入支出明细表（基础数据表）'!W88 -> 0 | K34: ='收入支出明细表（基础数据表）'!X88 -> 0 | L34: ='收入支出明细表（基础数据表）'!Y88 -> 0 | M34: ='收入支出明细表（基础数据表）'!Z88 -> 0 | N34: ='收入支出明细表（基础数据表）'!AA88 -> 0 | ... S34: ='收入支出明细表（基础数据表）'!AF88 -> 0
C35: 和教育 | D35: 收入 | F35: 0.06 | G35: ='收入支出明细表（基础数据表）'!T91 -> 0 | H35: ='收入支出明细表（基础数据表）'!U91 -> 0 | I35: ='收入支出明细表（基础数据表）'!V91 -> 0 | J35: ='收入支出明细表（基础数据表）'!W91 -> 0 | K35: ='收入支出明细表（基础数据表）'!X91 -> 0 | L35: ='收入支出明细表（基础数据表）'!Y91 -> 0 | M35: ='收入支出明细表（基础数据表）'!Z91 -> 0 | N35: ='收入支出明细表（基础数据表）'!AA91 -> 0 | ... S35: ='收入支出明细表（基础数据表）'!AF91 -> 0
C36: …… | G36: ='收入支出明细表（基础数据表）'!T94 -> 0 | H36: ='收入支出明细表（基础数据表）'!U94 -> 0 | I36: ='收入支出明细表（基础数据表）'!V94 -> 0 | J36: ='收入支出明细表（基础数据表）'!W94 -> 0 | K36: ='收入支出明细表（基础数据表）'!X94 -> 0 | L36: ='收入支出明细表（基础数据表）'!Y94 -> 0 | M36: ='收入支出明细表（基础数据表）'!Z94 -> 0 | N36: ='收入支出明细表（基础数据表）'!AA94 -> 0 | ... S36: ='收入支出明细表（基础数据表）'!AF94 -> 0
G37: ='收入支出明细表（基础数据表）'!T95 -> 0 | H37: ='收入支出明细表（基础数据表）'!U95 -> 0 | I37: ='收入支出明细表（基础数据表）'!V95 -> 0 | J37: ='收入支出明细表（基础数据表）'!W95 -> 0 | K37: ='收入支出明细表（基础数据表）'!X95 -> 0 | L37: ='收入支出明细表（基础数据表）'!Y95 -> 0 | M37: ='收入支出明细表（基础数据表）'!Z95 -> 0 | N37: ='收入支出明细表（基础数据表）'!AA95 -> 0 | ... S37: ='收入支出明细表（基础数据表）'!AF95 -> 0
A38: 投资支出 （Capex） | B38: 项目支出合计 | D38: 支出 | G38: ='收入支出明细表（基础数据表）'!T96 -> 0 | H38: ='收入支出明细表（基础数据表）'!U96 -> 0 | I38: ='收入支出明细表（基础数据表）'!V96 -> 0 | J38: ='收入支出明细表（基础数据表）'!W96 -> 0 | K38: ='收入支出明细表（基础数据表）'!X96 -> 0 | L38: ='收入支出明细表（基础数据表）'!Y96 -> 0 | M38: ='收入支出明细表（基础数据表）'!Z96 -> 0 | N38: ='收入支出明细表（基础数据表）'!AA96 -> 0 | ... S38: ='收入支出明细表（基础数据表）'!AF96 -> 0
B39: IT类投资 | C39: IT类投资合计 | D39: 支出 | G39: ='收入支出明细表（基础数据表）'!T99 -> 0 | H39: ='收入支出明细表（基础数据表）'!U99 -> 0 | I39: ='收入支出明细表（基础数据表）'!V99 -> 0 | J39: ='收入支出明细表（基础数据表）'!W99 -> 0 | K39: ='收入支出明细表（基础数据表）'!X99 -> 0 | L39: ='收入支出明细表（基础数据表）'!Y99 -> 0 | M39: ='收入支出明细表（基础数据表）'!Z99 -> 0 | N39: ='收入支出明细表（基础数据表）'!AA99 -> 0 | ... S39: ='收入支出明细表（基础数据表）'!AF99 -> 0
C40: 1、硬件设备类投资 | D40: 支出 | F40: 0.13 | G40: ='收入支出明细表（基础数据表）'!T102 -> 0 | H40: ='收入支出明细表（基础数据表）'!U102 -> 0 | I40: ='收入支出明细表（基础数据表）'!V102 -> 0 | J40: ='收入支出明细表（基础数据表）'!W102 -> 0 | K40: ='收入支出明细表（基础数据表）'!X102 -> 0 | L40: ='收入支出明细表（基础数据表）'!Y102 -> 0 | M40: ='收入支出明细表（基础数据表）'!Z102 -> 0 | N40: ='收入支出明细表（基础数据表）'!AA102 -> 0 | ... S40: ='收入支出明细表（基础数据表）'!AF102 -> 0
...

Sheet 现金流量明细表
B1: 参数 | C1: 月折现率 | D1: 所得税率
B2: 值 | C2: 0.05
B3: ICT项目现金流数据 (单位：元)
B4: 指标值 | C4: 金额（含税） | D4: 期初 | E4: 第1年 | F4: 第2年 | G4: 第3年 | H4: 第4年 | I4: 第5年 | J4: 第6年 | K4: 第7年 | L4: 第8年 | M4: 第9年 | N4: 第10年 | O4: …
B5: 现金流入合计 | C5: =SUM(D5:O5) -> 0 | D5: ='收入支出明细表（基础数据表）'!H4 -> 0 | E5: ='收入支出明细表（基础数据表）'!I4 -> 0 | F5: ='收入支出明细表（基础数据表）'!J4 -> 0 | G5: ='收入支出明细表（基础数据表）'!K4 -> 0 | H5: ='收入支出明细表（基础数据表）'!L4 -> 0 | I5: ='收入支出明细表（基础数据表）'!M4 -> 0 | J5: ='收入支出明细表（基础数据表）'!N4 -> 0 | K5: ='收入支出明细表（基础数据表）'!O4 -> 0 | ... O5: ='收入支出明细表（基础数据表）'!S4 -> 0
B6: 成本类现金流出 | C6: =SUM(D6:O6) -> 0 | D6: ='收入支出明细表（基础数据表）'!H141+'收入支出明细表（基础数据表）'!H172+'收入支出明细表（基础数据表）'!H191+'收入支出明细表（基础数据表）'!H216 -> 0 | E6: ='收入支出明细表（基础数据表）'!I141+'收入支出明细表（基础数据表）'!I172+'收入支出明细表（基础数据表）'!I191+'收入支出明细表（基础数据表）'!I216 -> 0 | F6: ='收入支出明细表（基础数据表）'!J141+'收入支出明细表（基础数据表）'!J172+'收入支出明细表（基础数据表）'!J191+'收入支出明细表（基础数据表）'!J216 -> 0 | G6: ='收入支出明细表（基础数据表）'!K141+'收入支出明细表（基础数据表）'!K172+'收入支出明细表（基础数据表）'!K191+'收入支出明细表（基础数据表）'!K216 -> 0 | H6: ='收入支出明细表（基础数据表）'!L141+'收入支出明细表（基础数据表）'!L172+'收入支出明细表（基础数据表）'!L191+'收入支出明细表（基础数据表）'!L216 -> 0 | I6: ='收入支出明细表（基础数据表）'!M141+'收入支出明细表（基础数据表）'!M172+'收入支出明细表（基础数据表）'!M191+'收入支出明细表（基础数据表）'!M216 -> 0 | J6: ='收入支出明细表（基础数据表）'!N141+'收入支出明细表（基础数据表）'!N172+'收入支出明细表（基础数据表）'!N191+'收入支出明细表（基础数据表）'!N216 -> 0 | K6: ='收入支出明细表（基础数据表）'!O141+'收入支出明细表（基础数据表）'!O172+'收入支出明细表（基础数据表）'!O191+'收入支出明细表（基础数据表）'!O216 -> 0 | ... O6: ='收入支出明细表（基础数据表）'!S141+'收入支出明细表（基础数据表）'!S172+'收入支出明细表（基础数据表）'!S191+'收入支出明细表（基础数据表）'!S216 -> 0
B7: 投资类现金流出 | C7: =SUM(D7:O7) -> 0 | D7: ='收入支出明细表（基础数据表）'!H100+'收入支出明细表（基础数据表）'!H122 -> 0 | E7: ='收入支出明细表（基础数据表）'!I100+'收入支出明细表（基础数据表）'!I122 -> 0 | F7: ='收入支出明细表（基础数据表）'!J100+'收入支出明细表（基础数据表）'!J122 -> 0 | G7: ='收入支出明细表（基础数据表）'!K100+'收入支出明细表（基础数据表）'!K122 -> 0 | H7: ='收入支出明细表（基础数据表）'!L100+'收入支出明细表（基础数据表）'!L122 -> 0 | I7: ='收入支出明细表（基础数据表）'!M100+'收入支出明细表（基础数据表）'!M122 -> 0 | J7: ='收入支出明细表（基础数据表）'!N100+'收入支出明细表（基础数据表）'!N122 -> 0 | K7: ='收入支出明细表（基础数据表）'!O100+'收入支出明细表（基础数据表）'!O122 -> 0 | ... O7: ='收入支出明细表（基础数据表）'!S100+'收入支出明细表（基础数据表）'!S122 -> 0
B8: 所得税支出 | C8: =C36 -> 0 | D8: =D36 -> 0 | E8: =E36 -> 0 | F8: =F36 -> 0 | G8: =G36 -> 0 | H8: =H36 -> 0 | I8: =I36 -> 0 | J8: =J36 -> 0 | ... O8: =O36 -> 0
B9: 现金流出合计 | C9: =SUM(C6:C8) -> 0 | D9: =SUM(D6:D8) -> 0 | E9: =SUM(E6:E8) -> 0 | F9: =SUM(F6:F8) -> 0 | G9: =SUM(G6:G8) -> 0 | H9: =SUM(H6:H8) -> 0 | I9: =SUM(I6:I8) -> 0 | J9: =SUM(J6:J8) -> 0 | ... O9: =SUM(O6:O8) -> 0
B10: 净现金流量 | C10: =SUM(D10:O10) -> 0 | D10: =D5-D9 -> 0 | E10: =E5-E9 -> 0 | F10: =F5-F9 -> 0 | G10: =G5-G9 -> 0 | H10: =H5-H9 -> 0 | I10: =I5-I9 -> 0 | J10: =J5-J9 -> 0 | K10: =K5-K9 -> 0 | ... O10: =O5-O9 -> 0
B11: 累计净现金流量 | C11: =N11 -> 0 | D11: =SUM($D10:D10) -> 0 | E11: =SUM($D10:E10) -> 0 | F11: =SUM($D10:F10) -> 0 | G11: =SUM($D10:G10) -> 0 | H11: =SUM($D10:H10) -> 0 | I11: =SUM($D10:I10) -> 0 | J11: =SUM($D10:J10) -> 0 | K11: =SUM($D10:K10) -> 0 | ... O11: =SUM($D10:O10) -> 0
B14: 相关现值指标计算表 （单位：元）
B15: 现值指标 | C15: 金额（含税） | D15: 第0年 | E15: 第1年 | F15: 第2年 | G15: 第3年 | H15: 第4年 | I15: 第5年 | J15: 第6年 | K15: 第7年 | L15: 第8年 | M15: 第9年 | N15: 第10年 | O15: …
B16: 净现值累计为正年份 | D16: =IF(D24<=0,1,0) -> 1 | E16: =IF(E24<=0,1,0) -> 1 | F16: =IF(F24<=0,1,0) -> 1 | G16: =IF(G24<=0,1,0) -> 1 | H16: =IF(H24<=0,1,0) -> 1 | I16: =IF(I24<=0,1,0) -> 1 | J16: =IF(J24<=0,1,0) -> 1 | K16: =IF(K24<=0,1,0) -> 1 | ... O16: =IF(O24<=0,1,0) -> 1
B17: 净现流累计为正年份 | D17: =IF(D11<=0,1,0) -> 1 | E17: =IF(E11<=0,1,0) -> 1 | F17: =IF(F11<=0,1,0) -> 1 | G17: =IF(G11<=0,1,0) -> 1 | H17: =IF(H11<=0,1,0) -> 1 | I17: =IF(I11<=0,1,0) -> 1 | J17: =IF(J11<=0,1,0) -> 1 | K17: =IF(K11<=0,1,0) -> 1 | ... O17: =IF(O11<=0,1,0) -> 1
B18: 指标值 | D18: 0 | E18: 1 | F18: 2 | G18: 3 | H18: 4 | I18: 5 | J18: 6 | K18: 7 | L18: 8 | M18: 9 | N18: 10 | O18: 11
B19: 现金流入现值 | C19: =SUM(D19:O19) -> 0 | D19: =D5/(1+$C$2)^D18 -> 0 | E19: =E5/(1+$C$2)^E18 -> 0 | F19: =F5/(1+$C$2)^F18 -> 0 | G19: =G5/(1+$C$2)^G18 -> 0 | H19: =H5/(1+$C$2)^H18 -> 0 | I19: =I5/(1+$C$2)^I18 -> 0 | J19: =J5/(1+$C$2)^J18 -> 0 | K19: =K5/(1+$C$2)^K18 -> 0 | ... O19: =O5/(1+$C$2)^O18 -> 0
B20: 现金流出现值 | C20: =SUM(D20:O20) -> 0 | D20: =D9/(1+$C$2)^D18 -> 0 | E20: =E9/(1+$C$2)^E18 -> 0 | F20: =F9/(1+$C$2)^F18 -> 0 | G20: =G9/(1+$C$2)^G18 -> 0 | H20: =H9/(1+$C$2)^H18 -> 0 | I20: =I9/(1+$C$2)^I18 -> 0 | J20: =J9/(1+$C$2)^J18 -> 0 | K20: =K9/(1+$C$2)^K18 -> 0 | ... O20: =O9/(1+$C$2)^O18 -> 0
B21: 净现金流量 | C21: =C10 -> 0 | D21: =D10 -> 0 | E21: =E10 -> 0 | F21: =F10 -> 0 | G21: =G10 -> 0 | H21: =H10 -> 0 | I21: =I10 -> 0 | J21: =J10 -> 0 | ... O21: =O10 -> 0
B22: 净现金流量现值 | C22: =SUM(D22:O22) -> 0 | D22: =D10/(1+$C$2)^D18 -> 0 | E22: =E10/(1+$C$2)^E18 -> 0 | F22: =F10/(1+$C$2)^F18 -> 0 | G22: =G10/(1+$C$2)^G18 -> 0 | H22: =H10/(1+$C$2)^H18 -> 0 | I22: =I10/(1+$C$2)^I18 -> 0 | J22: =J10/(1+$C$2)^J18 -> 0 | K22: =K10/(1+$C$2)^K18 -> 0 | ... O22: =O10/(1+$C$2)^O18 -> 0
B23: 累计净现金流量 | C23: =C11 -> 0 | D23: =D11 -> 0 | E23: =E11 -> 0 | F23: =F11 -> 0 | G23: =G11 -> 0 | H23: =H11 -> 0 | I23: =I11 -> 0 | J23: =J11 -> 0 | ... O23: =O11 -> 0
B24: 累计净现金流量现值 | C24: =N24 -> 0 | D24: =SUM($D22:D22) -> 0 | E24: =SUM($D22:E22) -> 0 | F24: =SUM($D22:F22) -> 0 | G24: =SUM($D22:G22) -> 0 | H24: =SUM($D22:H22) -> 0 | I24: =SUM($D22:I22) -> 0 | J24: =SUM($D22:J22) -> 0 | K24: =SUM($D22:K22) -> 0 | ... O24: =SUM($D22:O22) -> 0
B25: 投资类现金流出现值 | C25: =SUM(D25:O25) -> 0 | D25: =D7/(1+$C$2)^D18 -> 0 | E25: =E7/(1+$C$2)^E18 -> 0 | F25: =F7/(1+$C$2)^F18 -> 0 | G25: =G7/(1+$C$2)^G18 -> 0 | H25: =H7/(1+$C$2)^H18 -> 0 | I25: =I7/(1+$C$2)^I18 -> 0 | J25: =J7/(1+$C$2)^J18 -> 0 | K25: =K7/(1+$C$2)^K18 -> 0 | ... O25: =O7/(1+$C$2)^O18 -> 0
B26: 累计总投资现金流出现值 | C26: =C25 -> 0 | D26: =SUM($D25:D25) -> 0 | E26: =SUM($D25:E25) -> 0 | F26: =SUM($D25:F25) -> 0 | G26: =SUM($D25:G25) -> 0 | H26: =SUM($D25:H25) -> 0 | I26: =SUM($D25:I25) -> 0 | J26: =SUM($D25:J25) -> 0 | K26: =SUM($D25:K25) -> 0 | ... O26: =SUM($D25:O25) -> 0
B27: 成本类现金流出现值 | C27: =SUM(D27:O27) -> 0 | D27: =D6/(1+$C$2)^D18 -> 0 | E27: =E6/(1+$C$2)^E18 -> 0 | F27: =F6/(1+$C$2)^F18 -> 0 | G27: =G6/(1+$C$2)^G18 -> 0 | H27: =H6/(1+$C$2)^H18 -> 0 | I27: =I6/(1+$C$2)^I18 -> 0 | J27: =J6/(1+$C$2)^J18 -> 0 | K27: =K6/(1+$C$2)^K18 -> 0 | ... O27: =O6/(1+$C$2)^O18 -> 0
B28: 累计总成本现金流出现值 | C28: =C27 -> 0 | D28: =SUM($D27:D27) -> 0 | E28: =SUM($D27:E27) -> 0 | F28: =SUM($D27:F27) -> 0 | G28: =SUM($D27:G27) -> 0 | H28: =SUM($D27:H27) -> 0 | I28: =SUM($D27:I27) -> 0 | J28: =SUM($D27:J27) -> 0 | K28: =SUM($D27:K27) -> 0 | ... O28: =SUM($D27:O27) -> 0
B31: 所得税支出计算表 （单位：元）
B32: 数据类型 | C32: 金额（不含税） | D32: 第0年 | E32: 第1年 | F32: 第2年 | G32: 第3年 | H32: 第4年 | I32: 第5年 | J32: 第6年 | K32: 第7年 | L32: 第8年 | M32: 第9年 | N32: 第10年 | O32: …
B33: 项目收入合计 | C33: ='收入支出明细表（基础数据表）'!T3 -> 0 | D33: ='收入支出明细表（基础数据表）'!U3 -> 0 | E33: ='收入支出明细表（基础数据表）'!V3 -> 0 | F33: ='收入支出明细表（基础数据表）'!W3 -> 0 | G33: ='收入支出明细表（基础数据表）'!X3 -> 0 | H33: ='收入支出明细表（基础数据表）'!Y3 -> 0 | I33: ='收入支出明细表（基础数据表）'!Z3 -> 0 | J33: ='收入支出明细表（基础数据表）'!AA3 -> 0 | ... O33: ='收入支出明细表（基础数据表）'!AF3 -> 0
B34: 项目成本合计 | C34: ='收入支出明细表（基础数据表）'!T140+'收入支出明细表（基础数据表）'!T171+'收入支出明细表（基础数据表）'!T190+折旧及摊销辅助明细表!D4 -> 0 | D34: ='收入支出明细表（基础数据表）'!U140+'收入支出明细表（基础数据表）'!U171+'收入支出明细表（基础数据表）'!U190+折旧及摊销辅助明细表!E4 -> 0 | E34: ='收入支出明细表（基础数据表）'!V140+'收入支出明细表（基础数据表）'!V171+'收入支出明细表（基础数据表）'!V190+折旧及摊销辅助明细表!F4 -> 0 | F34: ='收入支出明细表（基础数据表）'!W140+'收入支出明细表（基础数据表）'!W171+'收入支出明细表（基础数据表）'!W190+折旧及摊销辅助明细表!G4 -> 0 | G34: ='收入支出明细表（基础数据表）'!X140+'收入支出明细表（基础数据表）'!X171+'收入支出明细表（基础数据表）'!X190+折旧及摊销辅助明细表!H4 -> 0 | H34: ='收入支出明细表（基础数据表）'!Y140+'收入支出明细表（基础数据表）'!Y171+'收入支出明细表（基础数据表）'!Y190+折旧及摊销辅助明细表!I4 -> 0 | I34: ='收入支出明细表（基础数据表）'!Z140+'收入支出明细表（基础数据表）'!Z171+'收入支出明细表（基础数据表）'!Z190+折旧及摊销辅助明细表!J4 -> 0 | J34: ='收入支出明细表（基础数据表）'!AA140+'收入支出明细表（基础数据表）'!AA171+'收入支出明细表（基础数据表）'!AA190+折旧及摊销辅助明细表!K4 -> 0 | ... O34: ='收入支出明细表（基础数据表）'!AF140+'收入支出明细表（基础数据表）'!AF171+'收入支出明细表（基础数据表）'!AF190+折旧及摊销辅助明细表!P4 -> 0
B35: 利润总额 | C35: =C33-C34 -> 0 | D35: =D33-D34 -> 0 | E35: =E33-E34 -> 0 | F35: =F33-F34 -> 0 | G35: =G33-G34 -> 0 | H35: =H33-H34 -> 0 | I35: =I33-I34 -> 0 | J35: =J33-J34 -> 0 | ... O35: =O33-O34 -> 0
B36: 所得税支出 | C36: =C35*$D$2 -> 0 | D36: =D35*$D$2 -> 0 | E36: =E35*$D$2 -> 0 | F36: =F35*$D$2 -> 0 | G36: =G35*$D$2 -> 0 | H36: =H35*$D$2 -> 0 | I36: =I35*$D$2 -> 0 | J36: =J35*$D$2 -> 0 | ... O36: =O35*$D$2 -> 0

Sheet 折旧及摊销辅助明细表
A1: 折旧及摊销辅助测算表
A2: 手工输入区
A3: 参考中国移动固定资产目录，平台类设备折旧年限为5年，传输网设备7年，光缆管道10年，软件类2-5年 | D3: 合计 | E3: 第0年 | F3: 第1年 | G3: 第2年 | H3: 第3年 | I3: 第4年 | J3: 第5年 | K3: 第6年 | L3: 第7年 | M3: 第8年 | N3: 第9年 | O3: 第10年 | P3: 第11年 | Q3: 第12年 | R3: 第13年 | S3: 第14年 | T3: 第15年 | U3: 第16年 | V3: 第17年 | W3: 第18年 | X3: 第19年
A4: 折旧及摊销 | B4: 总投资各年折旧及摊销 | D4: =SUM(E4:X4) -> 0 | E4: =E6+E22+E38+E54+E70 -> 0 | F4: =F6+F22+F38+F54+F70 -> 0 | G4: =G6+G22+G38+G54+G70 -> 0 | H4: =H6+H22+H38+H54+H70 -> 0 | I4: =I6+I22+I38+I54+I70 -> 0 | J4: =J6+J22+J38+J54+J70 -> 0 | K4: =K6+K22+K38+K54+K70 -> 0 | L4: =L6+L22+L38+L54+L70 -> 0 | ... X4: =X6+X22+X38+X54+X70 -> 0
B6: 平台类设备投资累计折旧 | D6: =SUM(E6:X6) -> 0 | E6: =SUM(E10:E20) -> 0 | F6: =SUM(F10:F20) -> 0 | G6: =SUM(G10:G20) -> 0 | H6: =SUM(H10:H20) -> 0 | I6: =SUM(I10:I20) -> 0 | J6: =SUM(J10:J20) -> 0 | K6: =SUM(K10:K20) -> 0 | L6: =SUM(L10:L20) -> 0 | ... X6: =SUM(X10:X20) -> 0
B7: 折旧年限 | C7: 5
B8: 当年转资月份 | F8: 0 | G8: 0 | H8: 0 | I8: 0 | J8: 0 | K8: 0 | L8: 0 | M8: 0 | N8: 0 | O8: 0
B9: 各年平台类设备转资规模 | D9: =SUM(E9:O9) -> 0
B10: 第一年投资在各年的折旧 | D10: =SUM(E10:X10) -> 0 | E10: =F10*(1-E8/12) -> 0 | F10: =E9/C7 -> 0 | G10: =IF(SUM(E10:F10)<E9,IF((E9-SUM(E10:F10))<E9/C7,E9-SUM(E10:F10),E9/C7),0) -> 0 | H10: =IF(SUM(E10:G10)<E9,IF((E9-SUM(E10:G10))<E9/C7,E9-SUM(E10:G10),E9/C7),0) -> 0 | I10: =IF(SUM(E10:H10)<E9,IF((E9-SUM(E10:H10))<E9/C7,E9-SUM(E10:H10),E9/C7),0) -> 0 | J10: =IF(SUM(E10:I10)<E9,IF((E9-SUM(E10:I10))<E9/C7,E9-SUM(E10:I10),E9/C7),0) -> 0 | K10: =IF(SUM(E10:J10)<E9,IF((E9-SUM(E10:J10))<E9/C7,E9-SUM(E10:J10),E9/C7),0) -> 0 | L10: =IF(SUM(E10:K10)<E9,IF((E9-SUM(E10:K10))<E9/C7,E9-SUM(E10:K10),E9/C7),0) -> 0 | M10: =IF(SUM(E10:L10)<E9,IF((E9-SUM(E10:L10))<E9/C7,E9-SUM(E10:L10),E9/C7),0) -> 0 | N10: =IF(SUM(E10:M10)<E9,IF((E9-SUM(E10:M10))<E9/C7,E9-SUM(E10:M10),E9/C7),0) -> 0 | O10: =IF(SUM(E10:N10)<E9,IF((E9-SUM(E10:N10))<E9/C7,E9-SUM(E10:N10),E9/C7),0) -> 0 | P10: =IF(SUM(E10:O10)<E9,IF((E9-SUM(E10:O10))<E9/C7,E9-SUM(E10:O10),E9/C7),0) -> 0 | Q10: =IF(SUM(E10:P10)<E9,IF((E9-SUM(E10:P10))<E9/C7,E9-SUM(E10:P10),E9/C7),0) -> 0 | R10: =IF(SUM(E10:Q10)<E9,IF((E9-SUM(E10:Q10))<E9/C7,E9-SUM(E10:Q10),E9/C7),0) -> 0 | S10: =IF(SUM(E10:R10)<E9,IF((E9-SUM(E10:R10))<E9/C7,E9-SUM(E10:R10),E9/C7),0) -> 0 | T10: =IF(SUM(E10:S10)<E9,IF((E9-SUM(E10:S10))<E9/C7,E9-SUM(E10:S10),E9/C7),0) -> 0 | U10: =IF(SUM(E10:T10)<E9,IF((E9-SUM(E10:T10))<E9/C7,E9-SUM(E10:T10),E9/C7),0) -> 0 | V10: =IF(SUM(E10:U10)<E9,IF((E9-SUM(E10:U10))<E9/C7,E9-SUM(E10:U10),E9/C7),0) -> 0 | W10: =IF(SUM(E10:V10)<E9,IF((E9-SUM(E10:V10))<E9/C7,E9-SUM(E10:V10),E9/C7),0) -> 0 | X10: =IF(SUM(E10:W10)<E9,IF((E9-SUM(E10:W10))<E9/C7,E9-SUM(E10:W10),E9/C7),0) -> 0
B11: 第二年投资在各年的折旧 | D11: =SUM(E11:X11) -> 0 | F11: =G11*(1-F8/12) -> 0 | G11: =F9/C7 -> 0 | H11: =IF(SUM(E11:G11)<F9,IF((F9-SUM(E11:G11))<F9/C7,F9-SUM(E11:G11),F9/C7),0) -> 0 | I11: =IF(SUM(E11:H11)<F9,IF((F9-SUM(E11:H11))<F9/C7,F9-SUM(E11:H11),F9/C7),0) -> 0 | J11: =IF(SUM(E11:I11)<F9,IF((F9-SUM(E11:I11))<F9/C7,F9-SUM(E11:I11),F9/C7),0) -> 0 | K11: =IF(SUM(E11:J11)<F9,IF((F9-SUM(E11:J11))<F9/C7,F9-SUM(E11:J11),F9/C7),0) -> 0 | L11: =IF(SUM(E11:K11)<F9,IF((F9-SUM(E11:K11))<F9/C7,F9-SUM(E11:K11),F9/C7),0) -> 0 | M11: =IF(SUM(E11:L11)<F9,IF((F9-SUM(E11:L11))<F9/C7,F9-SUM(E11:L11),F9/C7),0) -> 0 | N11: =IF(SUM(E11:M11)<F9,IF((F9-SUM(E11:M11))<F9/C7,F9-SUM(E11:M11),F9/C7),0) -> 0 | O11: =IF(SUM(E11:N11)<F9,IF((F9-SUM(E11:N11))<F9/C7,F9-SUM(E11:N11),F9/C7),0) -> 0 | P11: =IF(SUM(E11:O11)<F9,IF((F9-SUM(E11:O11))<F9/C7,F9-SUM(E11:O11),F9/C7),0) -> 0 | Q11: =IF(SUM(E11:P11)<F9,IF((F9-SUM(E11:P11))<F9/C7,F9-SUM(E11:P11),F9/C7),0) -> 0 | R11: =IF(SUM(E11:Q11)<F9,IF((F9-SUM(E11:Q11))<F9/C7,F9-SUM(E11:Q11),F9/C7),0) -> 0 | S11: =IF(SUM(E11:R11)<F9,IF((F9-SUM(E11:R11))<F9/C7,F9-SUM(E11:R11),F9/C7),0) -> 0 | T11: =IF(SUM(E11:S11)<F9,IF((F9-SUM(E11:S11))<F9/C7,F9-SUM(E11:S11),F9/C7),0) -> 0 | U11: =IF(SUM(E11:T11)<F9,IF((F9-SUM(E11:T11))<F9/C7,F9-SUM(E11:T11),F9/C7),0) -> 0 | V11: =IF(SUM(E11:U11)<F9,IF((F9-SUM(E11:U11))<F9/C7,F9-SUM(E11:U11),F9/C7),0) -> 0 | W11: =IF(SUM(E11:V11)<F9,IF((F9-SUM(E11:V11))<F9/C7,F9-SUM(E11:V11),F9/C7),0) -> 0 | X11: =IF(SUM(E11:W11)<F9,IF((F9-SUM(E11:W11))<F9/C7,F9-SUM(E11:W11),F9/C7),0) -> 0
B12: 第三年投资在各年的折旧 | D12: =SUM(E12:X12) -> 0 | G12: =H12*(1-G8/12) -> 0 | H12: =G9/C7 -> 0 | I12: =IF(SUM(E12:H12)<G9,IF((G9-SUM(E12:H12))<G9/C7,G9-SUM(E12:H12),G9/C7),0) -> 0 | J12: =IF(SUM(E12:I12)<G9,IF((G9-SUM(E12:I12))<G9/C7,G9-SUM(E12:I12),G9/C7),0) -> 0 | K12: =IF(SUM(E12:J12)<G9,IF((G9-SUM(E12:J12))<G9/C7,G9-SUM(E12:J12),G9/C7),0) -> 0 | L12: =IF(SUM(E12:K12)<G9,IF((G9-SUM(E12:K12))<G9/C7,G9-SUM(E12:K12),G9/C7),0) -> 0 | M12: =IF(SUM(E12:L12)<G9,IF((G9-SUM(E12:L12))<G9/C7,G9-SUM(E12:L12),G9/C7),0) -> 0 | N12: =IF(SUM(E12:M12)<G9,IF((G9-SUM(E12:M12))<G9/C7,G9-SUM(E12:M12),G9/C7),0) -> 0 | O12: =IF(SUM(E12:N12)<G9,IF((G9-SUM(E12:N12))<G9/C7,G9-SUM(E12:N12),G9/C7),0) -> 0 | P12: =IF(SUM(E12:O12)<G9,IF((G9-SUM(E12:O12))<G9/C7,G9-SUM(E12:O12),G9/C7),0) -> 0 | Q12: =IF(SUM(E12:P12)<G9,IF((G9-SUM(E12:P12))<G9/C7,G9-SUM(E12:P12),G9/C7),0) -> 0 | R12: =IF(SUM(E12:Q12)<G9,IF((G9-SUM(E12:Q12))<G9/C7,G9-SUM(E12:Q12),G9/C7),0) -> 0 | S12: =IF(SUM(E12:R12)<G9,IF((G9-SUM(E12:R12))<G9/C7,G9-SUM(E12:R12),G9/C7),0) -> 0 | T12: =IF(SUM(E12:S12)<G9,IF((G9-SUM(E12:S12))<G9/C7,G9-SUM(E12:S12),G9/C7),0) -> 0 | U12: =IF(SUM(E12:T12)<G9,IF((G9-SUM(E12:T12))<G9/C7,G9-SUM(E12:T12),G9/C7),0) -> 0 | V12: =IF(SUM(E12:U12)<G9,IF((G9-SUM(E12:U12))<G9/C7,G9-SUM(E12:U12),G9/C7),0) -> 0 | W12: =IF(SUM(E12:V12)<G9,IF((G9-SUM(E12:V12))<G9/C7,G9-SUM(E12:V12),G9/C7),0) -> 0 | X12: =IF(SUM(E12:W12)<G9,IF((G9-SUM(E12:W12))<G9/C7,G9-SUM(E12:W12),G9/C7),0) -> 0
B13: 第四年投资在各年的折旧 | D13: =SUM(E13:X13) -> 0 | H13: =I13*(1-H8/12) -> 0 | I13: =H9/C7 -> 0 | J13: =IF(SUM(E13:I13)<H9,IF((H9-SUM(E13:I13))<H9/C7,H9-SUM(E13:I13),H9/C7),0) -> 0 | K13: =IF(SUM(E13:J13)<H9,IF((H9-SUM(E13:J13))<H9/C7,H9-SUM(E13:J13),H9/C7),0) -> 0 | L13: =IF(SUM(E13:K13)<H9,IF((H9-SUM(E13:K13))<H9/C7,H9-SUM(E13:K13),H9/C7),0) -> 0 | M13: =IF(SUM(E13:L13)<H9,IF((H9-SUM(E13:L13))<H9/C7,H9-SUM(E13:L13),H9/C7),0) -> 0 | N13: =IF(SUM(E13:M13)<H9,IF((H9-SUM(E13:M13))<H9/C7,H9-SUM(E13:M13),H9/C7),0) -> 0 | O13: =IF(SUM(E13:N13)<H9,IF((H9-SUM(E13:N13))<H9/C7,H9-SUM(E13:N13),H9/C7),0) -> 0 | P13: =IF(SUM(E13:O13)<H9,IF((H9-SUM(E13:O13))<H9/C7,H9-SUM(E13:O13),H9/C7),0) -> 0 | Q13: =IF(SUM(E13:P13)<H9,IF((H9-SUM(E13:P13))<H9/C7,H9-SUM(E13:P13),H9/C7),0) -> 0 | R13: =IF(SUM(E13:Q13)<H9,IF((H9-SUM(E13:Q13))<H9/C7,H9-SUM(E13:Q13),H9/C7),0) -> 0 | S13: =IF(SUM(E13:R13)<H9,IF((H9-SUM(E13:R13))<H9/C7,H9-SUM(E13:R13),H9/C7),0) -> 0 | T13: =IF(SUM(E13:S13)<H9,IF((H9-SUM(E13:S13))<H9/C7,H9-SUM(E13:S13),H9/C7),0) -> 0 | U13: =IF(SUM(E13:T13)<H9,IF((H9-SUM(E13:T13))<H9/C7,H9-SUM(E13:T13),H9/C7),0) -> 0 | V13: =IF(SUM(E13:U13)<H9,IF((H9-SUM(E13:U13))<H9/C7,H9-SUM(E13:U13),H9/C7),0) -> 0 | W13: =IF(SUM(E13:V13)<H9,IF((H9-SUM(E13:V13))<H9/C7,H9-SUM(E13:V13),H9/C7),0) -> 0 | X13: =IF(SUM(E13:W13)<H9,IF((H9-SUM(E13:W13))<H9/C7,H9-SUM(E13:W13),H9/C7),0) -> 0
B14: 第五年投资在各年的折旧 | D14: =SUM(E14:X14) -> 0 | I14: =J14*(1-I8/12) -> 0 | J14: =I9/C7 -> 0 | K14: =IF(SUM(E14:J14)<I9,IF((I9-SUM(E14:J14))<I9/C7,I9-SUM(E14:J14),I9/C7),0) -> 0 | L14: =IF(SUM(E14:K14)<I9,IF((I9-SUM(E14:K14))<I9/C7,I9-SUM(E14:K14),I9/C7),0) -> 0 | M14: =IF(SUM(E14:L14)<I9,IF((I9-SUM(E14:L14))<I9/C7,I9-SUM(E14:L14),I9/C7),0) -> 0 | N14: =IF(SUM(E14:M14)<I9,IF((I9-SUM(E14:M14))<I9/C7,I9-SUM(E14:M14),I9/C7),0) -> 0 | O14: =IF(SUM(E14:N14)<I9,IF((I9-SUM(E14:N14))<I9/C7,I9-SUM(E14:N14),I9/C7),0) -> 0 | P14: =IF(SUM(E14:O14)<I9,IF((I9-SUM(E14:O14))<I9/C7,I9-SUM(E14:O14),I9/C7),0) -> 0 | Q14: =IF(SUM(E14:P14)<I9,IF((I9-SUM(E14:P14))<I9/C7,I9-SUM(E14:P14),I9/C7),0) -> 0 | R14: =IF(SUM(E14:Q14)<I9,IF((I9-SUM(E14:Q14))<I9/C7,I9-SUM(E14:Q14),I9/C7),0) -> 0 | S14: =IF(SUM(E14:R14)<I9,IF((I9-SUM(E14:R14))<I9/C7,I9-SUM(E14:R14),I9/C7),0) -> 0 | T14: =IF(SUM(E14:S14)<I9,IF((I9-SUM(E14:S14))<I9/C7,I9-SUM(E14:S14),I9/C7),0) -> 0 | U14: =IF(SUM(E14:T14)<I9,IF((I9-SUM(E14:T14))<I9/C7,I9-SUM(E14:T14),I9/C7),0) -> 0 | V14: =IF(SUM(E14:U14)<I9,IF((I9-SUM(E14:U14))<I9/C7,I9-SUM(E14:U14),I9/C7),0) -> 0 | W14: =IF(SUM(E14:V14)<I9,IF((I9-SUM(E14:V14))<I9/C7,I9-SUM(E14:V14),I9/C7),0) -> 0 | X14: =IF(SUM(E14:W14)<I9,IF((I9-SUM(E14:W14))<I9/C7,I9-SUM(E14:W14),I9/C7),0) -> 0
B15: 第六年投资在各年的折旧 | D15: =SUM(E15:X15) -> 0 | J15: =K15*(1-J8/12) -> 0 | K15: =J9/C7 -> 0 | L15: =IF(SUM(E15:K15)<J9,IF((J9-SUM(E15:K15))<J9/C7,J9-SUM(E15:K15),J9/C7),0) -> 0 | M15: =IF(SUM(E15:L15)<J9,IF((J9-SUM(E15:L15))<J9/C7,J9-SUM(E15:L15),J9/C7),0) -> 0 | N15: =IF(SUM(E15:M15)<J9,IF((J9-SUM(E15:M15))<J9/C7,J9-SUM(E15:M15),J9/C7),0) -> 0 | O15: =IF(SUM(E15:N15)<J9,IF((J9-SUM(E15:N15))<J9/C7,J9-SUM(E15:N15),J9/C7),0) -> 0 | P15: =IF(SUM(E15:O15)<J9,IF((J9-SUM(E15:O15))<J9/C7,J9-SUM(E15:O15),J9/C7),0) -> 0 | Q15: =IF(SUM(E15:P15)<J9,IF((J9-SUM(E15:P15))<J9/C7,J9-SUM(E15:P15),J9/C7),0) -> 0 | R15: =IF(SUM(E15:Q15)<J9,IF((J9-SUM(E15:Q15))<J9/C7,J9-SUM(E15:Q15),J9/C7),0) -> 0 | S15: =IF(SUM(E15:R15)<J9,IF((J9-SUM(E15:R15))<J9/C7,J9-SUM(E15:R15),J9/C7),0) -> 0 | T15: =IF(SUM(E15:S15)<J9,IF((J9-SUM(E15:S15))<J9/C7,J9-SUM(E15:S15),J9/C7),0) -> 0 | U15: =IF(SUM(E15:T15)<J9,IF((J9-SUM(E15:T15))<J9/C7,J9-SUM(E15:T15),J9/C7),0) -> 0 | V15: =IF(SUM(E15:U15)<J9,IF((J9-SUM(E15:U15))<J9/C7,J9-SUM(E15:U15),J9/C7),0) -> 0 | W15: =IF(SUM(E15:V15)<J9,IF((J9-SUM(E15:V15))<J9/C7,J9-SUM(E15:V15),J9/C7),0) -> 0 | X15: =IF(SUM(E15:W15)<J9,IF((J9-SUM(E15:W15))<J9/C7,J9-SUM(E15:W15),J9/C7),0) -> 0
B16: 第七年投资在各年的折旧 | D16: =SUM(E16:X16) -> 0 | K16: =L16*(1-K8/12) -> 0 | L16: =K9/C7 -> 0 | M16: =IF(SUM(E16:L16)<K9,IF((K9-SUM(E16:L16))<K9/C7,K9-SUM(E16:L16),K9/C7),0) -> 0 | N16: =IF(SUM(E16:M16)<K9,IF((K9-SUM(E16:M16))<K9/C7,K9-SUM(E16:M16),K9/C7),0) -> 0 | O16: =IF(SUM(E16:N16)<K9,IF((K9-SUM(E16:N16))<K9/C7,K9-SUM(E16:N16),K9/C7),0) -> 0 | P16: =IF(SUM(E16:O16)<K9,IF((K9-SUM(E16:O16))<K9/C7,K9-SUM(E16:O16),K9/C7),0) -> 0 | Q16: =IF(SUM(E16:P16)<K9,IF((K9-SUM(E16:P16))<K9/C7,K9-SUM(E16:P16),K9/C7),0) -> 0 | R16: =IF(SUM(E16:Q16)<K9,IF((K9-SUM(E16:Q16))<K9/C7,K9-SUM(E16:Q16),K9/C7),0) -> 0 | S16: =IF(SUM(E16:R16)<K9,IF((K9-SUM(E16:R16))<K9/C7,K9-SUM(E16:R16),K9/C7),0) -> 0 | T16: =IF(SUM(E16:S16)<K9,IF((K9-SUM(E16:S16))<K9/C7,K9-SUM(E16:S16),K9/C7),0) -> 0 | U16: =IF(SUM(E16:T16)<K9,IF((K9-SUM(E16:T16))<K9/C7,K9-SUM(E16:T16),K9/C7),0) -> 0 | V16: =IF(SUM(E16:U16)<K9,IF((K9-SUM(E16:U16))<K9/C7,K9-SUM(E16:U16),K9/C7),0) -> 0 | W16: =IF(SUM(E16:V16)<K9,IF((K9-SUM(E16:V16))<K9/C7,K9-SUM(E16:V16),K9/C7),0) -> 0 | X16: =IF(SUM(E16:W16)<K9,IF((K9-SUM(E16:W16))<K9/C7,K9-SUM(E16:W16),K9/C7),0) -> 0
